Workbook

Sheet 1and2
B2: 1 week of sale
C3: Uniform distribution | D3: 120 | E3: 420
C4: Expected sale= | D4: =AVERAGE(D3:E3) -> 270
C6: Cost=c= | D6: 3
C7: Selling price=p= | D7: $5 or $6
C8: Refund fraction= | D8: 0.5 | E8: [0.25-0.75 scenarios]
C9: Return shipping= | D9: 0.5 | E9: per unit
C10: K= | D10: 20 | E10: per order
C11: Prize value= | D11: 40000
A12: 1 | C12: Suppose selling price is $5. So Cost of Underage=5-3=$2; Cost of overage=3+0.5-3*0.5=2. So the right balance would be at the mid point and hence 270.
C13: This is because for every unit extra we don’t sell, it would cost $2 and every unit shortage we have, we loos $2 as well.
C14: We need to find the spot where P(D>=Q)=P(D<=Q)=Mean demand for the uniform distribution and in this case it is 270
C15: At $6 selling price, the custo of Underage=6-3=$3 while the cost of overage remains the same at $2. So it hurts to loose sales than have overages.
C16: So in this case, the tendence would be to keep higher stock than mid point and hence more than 270
A18: 2 | C18: At $5 selling price
B19: Co= | C19: 3-0.5*3+.5= | D19: =3-0.5*3+0.5 -> 2
B20: Cu= | C20: 5-3= | D20: =5-3 -> 2
B21: F(X*)= | C21: Cu/(Cu+Co)= | D21: =D20/(D20+D19) -> 0.5
B23: X*$5,0.5= | C23: =D21*($E$3-$D$3)+$D$3 -> 270 | D23: Expected Sales= | K23: =(270^2-120^2)/(2*300)+((420-270)*270)/300 -> 232.5
D24: Expected left over= | F24: =C23-K23 -> 37.5 | G24: a. | H24: Expected revenue= | J24: =$K23*5 -> 1162.5
G25: b. | H25: Salvage value of left over= | K25: =F24*$D$6*$D$8 -> 56.25
G26: c. | H26: Shipping cost= | J26: =F24*$D$9*-1 -> -18.75
G27: d. | H27: Ordering cost= | J27: =$D$10*-1 -> -20
G28: e. | H28: Variable buying cost= | J28: =C23*D6*-1 -> -810
I29: Expected Profit= | J29: a+b+c+d+e
I30: = | J30: =J27+J26+K25+J24+J28 -> 370
B32: Limitation of using uniform demand assumption:
B35: at $6 selling price
B36: Co= | C36: 3-0.5*3+.5= | D36: =3-0.5*3+0.5 -> 2
B37: Cu= | C37: 6-3= | D37: =6-3 -> 3
B38: F(X*)= | C38: Cu/(Cu+Co)= | D38: =D37/(D37+D36) -> 0.6
B40: X*$6,0.5= | C40: =D38*($E$3-$D$3)+$D$3 -> 300 | D40: Expected Sales= | K40: =(300^2-120^2)/(2*300)+((420-300)*300)/300 -> 246
D41: Expected left over= | F41: =C40-K40 -> 54 | G41: a. | H41: Expected revenue= | J41: =$K40*6 -> 1476
G42: b. | H42: Salvage value of left over= | K42: =F41*$D$6*$D$8 -> 81
G43: c. | H43: Shipping cost= | J43: =F41*$D$9*-1 -> -27
G44: d. | H44: Ordering cost= | J44: =$D$10*-1 -> -20
G45: e. | H45: Variable buying cost= | J45: =C40*D6*-1 -> -900
I46: Expected Profit= | J46: a+b+c+d+e
I47: = | J47: =J44+J43+K42+J41+J45 -> 610

Sheet 3
B2: 1 week of sale
C3: Uniform dist | D3: 120 | E3: 420
C4: Expected sale= | D4: =AVERAGE(D3:E3) -> 270
C6: Cost=c= | D6: 3
C7: Selling price=p= | D7: $5 or $6
C8: Refund fraction= | D8: 0.5 | E8: [0.25-0.75 scenarios]
C9: Return shipping= | D9: 0.5 | E9: per unit
C10: K= | D10: 20 | E10: per order
C11: Prize value= | D11: 40000
B14: at $5 selling price | D14: at 0.25 refund | F14: at 0.75 refund
B15: Co= | C15: 3-0.25*3+.5= | D15: =3-0.25*3+0.5 -> 2.75 | E15: 3-0.75*3+.5= | F15: =3-0.75*3+0.5 -> 1.25
B16: Cu= | C16: 5-3= | D16: =5-3 -> 2 | F16: =5-3 -> 2
B17: F(X*)= | C17: Cu/(Cu+Co)= | D17: =D16/(D16+D15) -> 0.42105263 | F17: =F16/(F16+F15) -> 0.61538462
D19: =D17*($E$3-$D$3)+$D$3 -> 246.31579 | F19: =F17*($E$3-$D$3)+$D$3 -> 304.61538
B20: at $6 selling price
B21: Co= | C21: 3-0.25*3+.5= | D21: =3-0.25*3+0.5 -> 2.75 | E21: 3-0.75*3+.5= | F21: =3-0.75*3+0.5 -> 1.25
B22: Cu= | C22: 6-3= | D22: =6-3 -> 3 | F22: =6-3 -> 3
B23: F(X*)= | C23: Cu/(Cu+Co)= | D23: =D22/(D22+D21) -> 0.52173913 | F23: =F22/(F22+F21) -> 0.70588235
B25: X*$6,0.25= | D25: =D23*(E3-D3)+D3 -> 276.52174 | F25: =F23*($E$3-$D$3)+$D$3 -> 331.76471

Sheet 4
B2: 1 week of sale | I2: 1 week of sale
C3: Uniform dist | D3: 120 | E3: 420 | J3: Uniform dist | K3: 120 | L3: 420
C4: Expected sale= | D4: =AVERAGE(D3:E3) -> 270 | J4: Expected sale= | K4: =AVERAGE(K3:L3) -> 270
C6: Cost=c= | D6: 3 | J6: Cost=c= | K6: 3
C7: Selling price=p= | D7: $5 or $6 | J7: Selling price=p= | K7: $5 or $6
C8: Refund fraction= | D8: 0.5 | E8: [0.25-0.75 scenarios] | J8: Refund fraction= | K8: 0.5 | L8: [0.25-0.75 scenarios]
C9: Return shipping= | D9: 0.5 | E9: per unit | J9: Return shipping= | K9: 0.5 | L9: per unit
C10: K= | D10: 20 | E10: per order | J10: K= | K10: 20 | L10: per order
C11: Prize value= | D11: 40000 | J11: Prize value= | K11: 40000
B20: at $6 selling price | D20: at 0.5 refund | I20: at $5 selling price | K20: at 0.5 refund
B21: Co= | C21: 3-0.5*3+.5= | D21: =3-0.5*3+0.5 -> 2 | I21: Co= | J21: 3-0.5*3+.5= | K21: =3-0.5*3+0.5 -> 2
B22: Cu= | C22: 6-3= | D22: =6-3 -> 3 | I22: Cu= | J22: 5-3= | K22: =5-3 -> 2
B23: F(X*)= | C23: Cu/(Cu+Co)= | D23: =D22/(D22+D21) -> 0.6 | I23: F(X*)= | J23: Cu/(Cu+Co)= | K23: =K22/(K22+K21) -> 0.5
B25: X*= | D25: =D23*(E3-D3)+D3 -> 300 | I25: X*= | K25: =K23*(L3-K3)+K3 -> 270
B26: Expected Sales= | G26: =(300^2-120^2)/(2*300)+((420-300)*300)/300 -> 246 | I26: Expected Sales= | N26: =(270^2-120^2)/(2*300)+((420-270)*270)/300 -> 232.5
B27: Expected left over= | C27: =D25-G26 -> 54 | D27: a. | E27: Expected revenue= | G27: =$G26*6 -> 1476 | I27: Expected left over= | J27: =K25-N26 -> 37.5 | K27: a. | L27: Expected revenue= | N27: =$N26*5 -> 1162.5
D28: b. | E28: Salvage value of left over= | G28: =C27*$D$6*$D$8 -> 81 | K28: b. | L28: Salvage value of left over= | N28: =J27*$D$6*$D$8 -> 56.25
D29: c. | E29: Shipping cost= | G29: =C27*$D$9*-1 -> -27 | K29: c. | L29: Shipping cost= | N29: =J27*$D$9*-1 -> -18.75
D30: d. | E30: Ordering cost= | G30: =$D$10*-1 -> -20 | K30: d. | L30: Ordering cost= | N30: =$D$10*-1 -> -20
D31: e. | E31: Variable buying cost= | G31: =-1*D25*D6 -> -900 | K31: e. | L31: Variable buying cost= | N31: =-1*K25*K6 -> -810
F32: Expected Profit= | G32: a+b+c+d+e | M32: Expected Profit= | N32: a+b+c+d+e
F33: = | G33: =G30+G29+G28+G27+G31 -> 610 | M33: = | N33: =N30+N29+N28+N27+N31 -> 370
A36: Would would happen if raising prices changes demand?

Sheet 5
B2: 1 week of sale
C3: Uniform dist | D3: 120 | E3: 420
C4: Expected sale= | D4: =AVERAGE(D3:E3) -> 270 | I4: S.no | J4: Demand | K4: Units sold | L4: Left over units | M4: Revenue | N4: Setup cost | O4: Cost - Var | P4: Cost-shipping | Q4: Refund | R4: Net Profit | S4: count of loss
I5: 1 | J5: =RAND()*($E$3-$D$3)+$D$3 -> 280.42644 | K5: =IF(J5>=$D$18,$D$18,$D$18-J5) -> 270 | L5: =$D$18-K5 -> 0 | M5: =K5*5 -> 1350 | N5: =$D$10 -> 20 | O5: =-$D$6*$D$18 -> -810 | P5: =-L5*$D$9 -> 0 | Q5: =L5*($D$6*$D$8) -> 0 | R5: =SUM(M5:Q5) -> 560 | S5: =IF(R5<0,1,0) -> 0
C6: Cost=c= | D6: 3 | I6: =I5+1 -> 2 | J6: =RAND()*($E$3-$D$3)+$D$3 -> 151.08885 | K6: =IF(J6>=$D$18,$D$18,$D$18-J6) -> 118.91115 | L6: =$D$18-K6 -> 151.08885 | M6: =K6*5 -> 594.55573 | N6: =$D$10 -> 20 | O6: =-$D$6*$D$18 -> -810 | P6: =-L6*$D$9 -> -75.544427 | Q6: =L6*($D$6*$D$8) -> 226.63328 | R6: =SUM(M6:Q6) -> -44.355418 | S6: =IF(R6<0,1,0) -> 1
C7: Selling price=p= | D7: $5 or $6 | I7: =I6+1 -> 3 | J7: =RAND()*($E$3-$D$3)+$D$3 -> 225.07691 | K7: =IF(J7>=$D$18,$D$18,$D$18-J7) -> 44.923092 | L7: =$D$18-K7 -> 225.07691 | M7: =K7*5 -> 224.61546 | N7: =$D$10 -> 20 | O7: =-$D$6*$D$18 -> -810 | P7: =-L7*$D$9 -> -112.53845 | Q7: =L7*($D$6*$D$8) -> 337.61536 | R7: =SUM(M7:Q7) -> -340.30763 | S7: =IF(R7<0,1,0) -> 1
C8: Refund fraction= | D8: 0.5 | E8: [0.25-0.75 scenarios] | I8: =I7+1 -> 4 | J8: =RAND()*($E$3-$D$3)+$D$3 -> 314.19297 | K8: =IF(J8>=$D$18,$D$18,$D$18-J8) -> 270 | L8: =$D$18-K8 -> 0 | M8: =K8*5 -> 1350 | N8: =$D$10 -> 20 | O8: =-$D$6*$D$18 -> -810 | P8: =-L8*$D$9 -> 0 | Q8: =L8*($D$6*$D$8) -> 0 | R8: =SUM(M8:Q8) -> 560 | S8: =IF(R8<0,1,0) -> 0
C9: Return shipping= | D9: 0.5 | E9: per unit | I9: =I8+1 -> 5 | J9: =RAND()*($E$3-$D$3)+$D$3 -> 294.39882 | K9: =IF(J9>=$D$18,$D$18,$D$18-J9) -> 270 | L9: =$D$18-K9 -> 0 | M9: =K9*5 -> 1350 | N9: =$D$10 -> 20 | O9: =-$D$6*$D$18 -> -810 | P9: =-L9*$D$9 -> 0 | Q9: =L9*($D$6*$D$8) -> 0 | R9: =SUM(M9:Q9) -> 560 | S9: =IF(R9<0,1,0) -> 0
C10: K= | D10: 20 | E10: per order | I10: =I9+1 -> 6 | J10: =RAND()*($E$3-$D$3)+$D$3 -> 243.1594 | K10: =IF(J10>=$D$18,$D$18,$D$18-J10) -> 26.840599 | L10: =$D$18-K10 -> 243.1594 | M10: =K10*5 -> 134.203 | N10: =$D$10 -> 20 | O10: =-$D$6*$D$18 -> -810 | P10: =-L10*$D$9 -> -121.5797 | Q10: =L10*($D$6*$D$8) -> 364.7391 | R10: =SUM(M10:Q10) -> -412.6376 | S10: =IF(R10<0,1,0) -> 1
C11: Prize value= | D11: 40000 | I11: =I10+1 -> 7 | J11: =RAND()*($E$3-$D$3)+$D$3 -> 403.21711 | K11: =IF(J11>=$D$18,$D$18,$D$18-J11) -> 270 | L11: =$D$18-K11 -> 0 | M11: =K11*5 -> 1350 | N11: =$D$10 -> 20 | O11: =-$D$6*$D$18 -> -810 | P11: =-L11*$D$9 -> 0 | Q11: =L11*($D$6*$D$8) -> 0 | R11: =SUM(M11:Q11) -> 560 | S11: =IF(R11<0,1,0) -> 0
I12: =I11+1 -> 8 | J12: =RAND()*($E$3-$D$3)+$D$3 -> 252.63719 | K12: =IF(J12>=$D$18,$D$18,$D$18-J12) -> 17.362807 | L12: =$D$18-K12 -> 252.63719 | M12: =K12*5 -> 86.814037 | N12: =$D$10 -> 20 | O12: =-$D$6*$D$18 -> -810 | P12: =-L12*$D$9 -> -126.3186 | Q12: =L12*($D$6*$D$8) -> 378.95579 | R12: =SUM(M12:Q12) -> -450.54877 | S12: =IF(R12<0,1,0) -> 1
B13: at $5 selling price | D13: at 0.5 refund | I13: =I12+1 -> 9 | J13: =RAND()*($E$3-$D$3)+$D$3 -> 227.20731 | K13: =IF(J13>=$D$18,$D$18,$D$18-J13) -> 42.792685 | L13: =$D$18-K13 -> 227.20731 | M13: =K13*5 -> 213.96343 | N13: =$D$10 -> 20 | O13: =-$D$6*$D$18 -> -810 | P13: =-L13*$D$9 -> -113.60366 | Q13: =L13*($D$6*$D$8) -> 340.81097 | R13: =SUM(M13:Q13) -> -348.82926 | S13: =IF(R13<0,1,0) -> 1
B14: Co= | C14: 3-0.5*3+.5= | D14: =3-0.5*3+0.5 -> 2 | I14: =I13+1 -> 10 | J14: =RAND()*($E$3-$D$3)+$D$3 -> 215.36934 | K14: =IF(J14>=$D$18,$D$18,$D$18-J14) -> 54.630661 | L14: =$D$18-K14 -> 215.36934 | M14: =K14*5 -> 273.15331 | N14: =$D$10 -> 20 | O14: =-$D$6*$D$18 -> -810 | P14: =-L14*$D$9 -> -107.68467 | Q14: =L14*($D$6*$D$8) -> 323.05401 | R14: =SUM(M14:Q14) -> -301.47735 | S14: =IF(R14<0,1,0) -> 1
B15: Cu= | C15: 5-3= | D15: =5-3 -> 2 | I15: =I14+1 -> 11 | J15: =RAND()*($E$3-$D$3)+$D$3 -> 279.66768 | K15: =IF(J15>=$D$18,$D$18,$D$18-J15) -> 270 | L15: =$D$18-K15 -> 0 | M15: =K15*5 -> 1350 | N15: =$D$10 -> 20 | O15: =-$D$6*$D$18 -> -810 | P15: =-L15*$D$9 -> 0 | Q15: =L15*($D$6*$D$8) -> 0 | R15: =SUM(M15:Q15) -> 560 | S15: =IF(R15<0,1,0) -> 0
B16: F(X*)= | C16: Cu/(Cu+Co)= | D16: =D15/(D15+D14) -> 0.5 | I16: =I15+1 -> 12 | J16: =RAND()*($E$3-$D$3)+$D$3 -> 240.06514 | K16: =IF(J16>=$D$18,$D$18,$D$18-J16) -> 29.934861 | L16: =$D$18-K16 -> 240.06514 | M16: =K16*5 -> 149.6743 | N16: =$D$10 -> 20 | O16: =-$D$6*$D$18 -> -810 | P16: =-L16*$D$9 -> -120.03257 | Q16: =L16*($D$6*$D$8) -> 360.09771 | R16: =SUM(M16:Q16) -> -400.26056 | S16: =IF(R16<0,1,0) -> 1
I17: =I16+1 -> 13 | J17: =RAND()*($E$3-$D$3)+$D$3 -> 307.2258 | K17: =IF(J17>=$D$18,$D$18,$D$18-J17) -> 270 | L17: =$D$18-K17 -> 0 | M17: =K17*5 -> 1350 | N17: =$D$10 -> 20 | O17: =-$D$6*$D$18 -> -810 | P17: =-L17*$D$9 -> 0 | Q17: =L17*($D$6*$D$8) -> 0 | R17: =SUM(M17:Q17) -> 560 | S17: =IF(R17<0,1,0) -> 0
B18: X*= | D18: =D16*(E3-D3)+D3 -> 270 | I18: =I17+1 -> 14 | J18: =RAND()*($E$3-$D$3)+$D$3 -> 294.61527 | K18: =IF(J18>=$D$18,$D$18,$D$18-J18) -> 270 | L18: =$D$18-K18 -> 0 | M18: =K18*5 -> 1350 | N18: =$D$10 -> 20 | O18: =-$D$6*$D$18 -> -810 | P18: =-L18*$D$9 -> 0 | Q18: =L18*($D$6*$D$8) -> 0 | R18: =SUM(M18:Q18) -> 560 | S18: =IF(R18<0,1,0) -> 0
I19: =I18+1 -> 15 | J19: =RAND()*($E$3-$D$3)+$D$3 -> 258.77872 | K19: =IF(J19>=$D$18,$D$18,$D$18-J19) -> 11.221275 | L19: =$D$18-K19 -> 258.77872 | M19: =K19*5 -> 56.106377 | N19: =$D$10 -> 20 | O19: =-$D$6*$D$18 -> -810 | P19: =-L19*$D$9 -> -129.38936 | Q19: =L19*($D$6*$D$8) -> 388.16809 | R19: =SUM(M19:Q19) -> -475.1149 | S19: =IF(R19<0,1,0) -> 1
I20: =I19+1 -> 16 | J20: =RAND()*($E$3-$D$3)+$D$3 -> 125.71439 | K20: =IF(J20>=$D$18,$D$18,$D$18-J20) -> 144.28561 | L20: =$D$18-K20 -> 125.71439 | M20: =K20*5 -> 721.42806 | N20: =$D$10 -> 20 | O20: =-$D$6*$D$18 -> -810 | P20: =-L20*$D$9 -> -62.857194 | Q20: =L20*($D$6*$D$8) -> 188.57158 | R20: =SUM(M20:Q20) -> 57.142447 | S20: =IF(R20<0,1,0) -> 0
I21: =I20+1 -> 17 | J21: =RAND()*($E$3-$D$3)+$D$3 -> 204.36987 | K21: =IF(J21>=$D$18,$D$18,$D$18-J21) -> 65.630132 | L21: =$D$18-K21 -> 204.36987 | M21: =K21*5 -> 328.15066 | N21: =$D$10 -> 20 | O21: =-$D$6*$D$18 -> -810 | P21: =-L21*$D$9 -> -102.18493 | Q21: =L21*($D$6*$D$8) -> 306.5548 | R21: =SUM(M21:Q21) -> -257.47947 | S21: =IF(R21<0,1,0) -> 1
I22: =I21+1 -> 18 | J22: =RAND()*($E$3-$D$3)+$D$3 -> 239.92092 | K22: =IF(J22>=$D$18,$D$18,$D$18-J22) -> 30.079083 | L22: =$D$18-K22 -> 239.92092 | M22: =K22*5 -> 150.39541 | N22: =$D$10 -> 20 | O22: =-$D$6*$D$18 -> -810 | P22: =-L22*$D$9 -> -119.96046 | Q22: =L22*($D$6*$D$8) -> 359.88138 | R22: =SUM(M22:Q22) -> -399.68367 | S22: =IF(R22<0,1,0) -> 1
I23: =I22+1 -> 19 | J23: =RAND()*($E$3-$D$3)+$D$3 -> 417.18961 | K23: =IF(J23>=$D$18,$D$18,$D$18-J23) -> 270 | L23: =$D$18-K23 -> 0 | M23: =K23*5 -> 1350 | N23: =$D$10 -> 20 | O23: =-$D$6*$D$18 -> -810 | P23: =-L23*$D$9 -> 0 | Q23: =L23*($D$6*$D$8) -> 0 | R23: =SUM(M23:Q23) -> 560 | S23: =IF(R23<0,1,0) -> 0
I24: =I23+1 -> 20 | J24: =RAND()*($E$3-$D$3)+$D$3 -> 386.53682 | K24: =IF(J24>=$D$18,$D$18,$D$18-J24) -> 270 | L24: =$D$18-K24 -> 0 | M24: =K24*5 -> 1350 | N24: =$D$10 -> 20 | O24: =-$D$6*$D$18 -> -810 | P24: =-L24*$D$9 -> 0 | Q24: =L24*($D$6*$D$8) -> 0 | R24: =SUM(M24:Q24) -> 560 | S24: =IF(R24<0,1,0) -> 0
I25: =I24+1 -> 21 | J25: =RAND()*($E$3-$D$3)+$D$3 -> 189.7084 | K25: =IF(J25>=$D$18,$D$18,$D$18-J25) -> 80.291596 | L25: =$D$18-K25 -> 189.7084 | M25: =K25*5 -> 401.45798 | N25: =$D$10 -> 20 | O25: =-$D$6*$D$18 -> -810 | P25: =-L25*$D$9 -> -94.854202 | Q25: =L25*($D$6*$D$8) -> 284.56261 | R25: =SUM(M25:Q25) -> -198.83362 | S25: =IF(R25<0,1,0) -> 1
I26: =I25+1 -> 22 | J26: =RAND()*($E$3-$D$3)+$D$3 -> 132.01556 | K26: =IF(J26>=$D$18,$D$18,$D$18-J26) -> 137.98444 | L26: =$D$18-K26 -> 132.01556 | M26: =K26*5 -> 689.92219 | N26: =$D$10 -> 20 | O26: =-$D$6*$D$18 -> -810 | P26: =-L26*$D$9 -> -66.007781 | Q26: =L26*($D$6*$D$8) -> 198.02334 | R26: =SUM(M26:Q26) -> 31.937756 | S26: =IF(R26<0,1,0) -> 0
I27: =I26+1 -> 23 | J27: =RAND()*($E$3-$D$3)+$D$3 -> 157.39177 | K27: =IF(J27>=$D$18,$D$18,$D$18-J27) -> 112.60823 | L27: =$D$18-K27 -> 157.39177 | M27: =K27*5 -> 563.04113 | N27: =$D$10 -> 20 | O27: =-$D$6*$D$18 -> -810 | P27: =-L27*$D$9 -> -78.695887 | Q27: =L27*($D$6*$D$8) -> 236.08766 | R27: =SUM(M27:Q27) -> -69.567098 | S27: =IF(R27<0,1,0) -> 1
I28: =I27+1 -> 24 | J28: =RAND()*($E$3-$D$3)+$D$3 -> 405.49312 | K28: =IF(J28>=$D$18,$D$18,$D$18-J28) -> 270 | L28: =$D$18-K28 -> 0 | M28: =K28*5 -> 1350 | N28: =$D$10 -> 20 | O28: =-$D$6*$D$18 -> -810 | P28: =-L28*$D$9 -> 0 | Q28: =L28*($D$6*$D$8) -> 0 | R28: =SUM(M28:Q28) -> 560 | S28: =IF(R28<0,1,0) -> 0
I29: =I28+1 -> 25 | J29: =RAND()*($E$3-$D$3)+$D$3 -> 264.45488 | K29: =IF(J29>=$D$18,$D$18,$D$18-J29) -> 5.5451158 | L29: =$D$18-K29 -> 264.45488 | M29: =K29*5 -> 27.725579 | N29: =$D$10 -> 20 | O29: =-$D$6*$D$18 -> -810 | P29: =-L29*$D$9 -> -132.22744 | Q29: =L29*($D$6*$D$8) -> 396.68233 | R29: =SUM(M29:Q29) -> -497.81954 | S29: =IF(R29<0,1,0) -> 1
I30: =I29+1 -> 26 | J30: =RAND()*($E$3-$D$3)+$D$3 -> 160.51399 | K30: =IF(J30>=$D$18,$D$18,$D$18-J30) -> 109.48601 | L30: =$D$18-K30 -> 160.51399 | M30: =K30*5 -> 547.43005 | N30: =$D$10 -> 20 | O30: =-$D$6*$D$18 -> -810 | P30: =-L30*$D$9 -> -80.256995 | Q30: =L30*($D$6*$D$8) -> 240.77099 | R30: =SUM(M30:Q30) -> -82.055964 | S30: =IF(R30<0,1,0) -> 1
... I504: =I503+1 -> 500 | J504: =RAND()*($E$3-$D$3)+$D$3 -> 390.49856 | K504: =IF(J504>=$D$18,$D$18,$D$18-J504) -> 270 | L504: =$D$18-K504 -> 0 | M504: =K504*5 -> 1350 | N504: =$D$10 -> 20 | O504: =-$D$6*$D$18 -> -810 | P504: =-L504*$D$9 -> 0 | Q504: =L504*($D$6*$D$8) -> 0 | R504: =SUM(M504:Q504) -> 560 | S504: =IF(R504<0,1,0) -> 0
Q505: Avg Profit[500 simulation] | R505: =AVERAGE(R5:R504) -> 160.13906
Q506: E[Profit] | R506: ='4'!N33 -> 370
Q507: Std Dev of Profit | R507: =STDEV(R5:R504) -> 412.61786
Q508: No. of instance of loss | R508: =SUM(S5:S504) -> 218
Q509: P(loss)= | R509: =R508/500 -> 0.436

Sheet 6
N3: Leisure Limited awards $40,000 to the stand with highest sales. SparkFire estimates a
B4: a) | C4: From 1,2,3 we have below X* at various Selling prices and fraction as refund | N4: 5% chance of winning if actual sales are ≥400 units. Other states use 3% if actual sales
E5: X* at various fractions of refund | N5: ≥380 or 7% if actual sales ≥420 are mentioned as context.
E6: 0.25 | F6: 0.5 | G6: 0.75 | N6: (a) Modify your profit model to account for the possibility of awards.
C7: Sellling Price | D7: 5 | E7: ='3'!D19 -> 246.31579 | F7: ='1and2'!C23 -> 270 | G7: ='3'!F19 -> 304.61538 | N7: (b) Find the new quantity Q∗∗ that maximizes total expected returns.
D8: 6 | E8: ='3'!D25 -> 276.52174 | F8: ='1and2'!C40 -> 300 | G8: ='3'!F25 -> 331.76471 | N8: (c) Compare Q∗∗ to Q∗ (from Part 2) and discuss how this incentive scheme encourages
N9: risk-seeking or risk-averse behavior.
C10: Now below are the changes of winning
D12: Sales | E12: Probability of winning | G12: Correspond X*
D13: >=400 | E13: 0.05 | G13: Nil
D14: >=380 | E14: 0.03 | G14: Nil
D15: >=420 | E15: 0.07 | G15: Nil
C17: Lets find X* with below add ons
C18: 1. Assuming sales >=400, then Addional revenue=40000*.05= | H18: =40000*0.05 -> 2000 | I18: overall; So per unit on 400 (minimum qty)= | M18: =2000/400 -> 5 | N18: $per unit
C19: So Cu=5+5-3= | E19: =2+5 -> 7
C20: Co=3-0.5*3+.5= | E20: =3-0.5*3+0.5 -> 2
C21: So F(X*)= | E21: =E19/(E20+E19) -> 0.77777778
C22: X*= | E22: =E21*(420-120)+120 -> 353.33333 | G22: at 0.5 refund fraction
C24: 1. Assuming X* >=380, then Addional revenue=40000*.03= | H24: =40000*0.03 -> 1200 | I24: overall; So per unit on 380 (minimum qty)= | M24: =1200/380 -> 3.1578947 | N24: $per unit
C25: So Cu=5+3.2-3= | E25: =2+3.2 -> 5.2
C26: Co=3-0.5*3+.5= | E26: =3-0.5*3+0.5 -> 2
C27: So F(X*)= | E27: =E25/(E26+E25) -> 0.72222222
C28: X*= | E28: =E27*(420-120)+120 -> 336.66667 | G28: at 0.5 refund fraction

Sheet 7
E4: Optimal qty at unit cost | T4: Expected left over | U4: Salvage value | V4: Shipping cost | W4: Net Profit
B5: Order Qty | C5: Unit cost | E5: (@ $5 selling price) | G5: (@ $6 selling price) | I5: Comment | L5: Total cost at | M5: Cost Total | N5: Expected Sale qty
B6: 1-199 | C6: 3 | E6: ='1and2'!C23 -> 270 | G6: ='1and2'!C40 -> 300 | I6: Beyond order qty range for that cost | L6: 199 units= | M6: =(199*3+G25)*-1 -> -617 | S6: =(199^2-120^2)/(2*300)+((420-199)*199)/300 -> 188.59833 | T6: =199-S6 -> 10.401667 | U6: =T6*$G$23*C6 -> 15.6025 | V6: =T6*$G$24*-1 -> -5.2008333 | W6: =S6*$G$22+V6+U6+M6 -> 336.39333
B8: 200-399 | C8: 2.85 | E8: =F34 -> 278.28221 | I8: within the range so this should be ordered | L8: =TEXT(E8,"0.00") & " units" -> 278.28 units | M8: =(E8*C8+20)*-1 -> -813.10429 | S8: =(278.28^2-120^2)/(2*300)+((420-278.28)*278.28)/300 -> 236.52574 | T8: =278-S8 -> 41.474264 | U8: =T8*$G$23*C8 -> 59.100826 | V8: =T8*$G$24*-1 -> -20.737132 | W8: =S8*$G$22+V8+U8+M8 -> 407.88808
B10: 400+ | C10: 2.7 | E10: =L34 -> 286.26506 | I10: Below the range of 400 so we use 400 | L10: 400 | M10: =(E10*C10+20)*-1 -> -792.91566 | S10: =(400^2-120^2)/(2*300)+((420-400)*400)/300 -> 269.33333 | T10: =400-S10 -> 130.66667 | U10: =T10*$G$23*C10 -> 176.4 | V10: =T10*$G$24*-1 -> -65.333333 | W10: =S10*$G$22+V10+U10+M10 -> 664.81767
E17: 1 week of sale | K17: 1 week of sale
F18: Uniform dist | G18: 120 | H18: 420 | L18: Uniform dist | M18: 120 | N18: 420
F19: Expected sale= | G19: =AVERAGE(G18:H18) -> 270 | L19: Expected sale= | M19: =AVERAGE(M18:N18) -> 270
F21: Cost=c= | G21: =C8 -> 2.85 | L21: Cost=c= | M21: =C10 -> 2.7
F22: Selling price=p= | G22: 5 | L22: Selling price=p= | M22: 5
F23: Refund fraction= | G23: 0.5 | H23: [0.25-0.75 scenarios] | L23: Refund fraction= | M23: 0.5 | N23: [0.25-0.75 scenarios]
F24: Return shipping= | G24: 0.5 | H24: per unit | L24: Return shipping= | M24: 0.5 | N24: per unit
F25: K= | G25: 20 | H25: per order | L25: K= | M25: 20 | N25: per order
F26: Prize value= | G26: 40000 | L26: Prize value= | M26: 40000
E29: at $5 selling price | K29: at $5 selling price
E30: Co= | F30: 2.85-0.5*2.85+.5= | G30: =G21-0.5*G21+0.5 -> 1.925 | K30: Co= | L30: 2.85-0.5*2.85+.5= | M30: =M21-0.5*M21+0.5 -> 1.85
E31: Cu= | F31: 5-3= | G31: =5-G21 -> 2.15 | K31: Cu= | L31: 5-3= | M31: =5-M21 -> 2.3
E32: F(X*)= | F32: Cu/(Cu+Co)= | G32: =G31/(G31+G30) -> 0.52760736 | K32: F(X*)= | L32: Cu/(Cu+Co)= | M32: =M31/(M31+M30) -> 0.55421687
E34: X*$5,0.5= | F34: =G32*(420-120)+120 -> 278.28221 | K34: X*$5,0.5= | L34: =M32*(420-120)+120 -> 286.26506

Sheet 8
E1: f= | F1: 0.5 | G1: % of cost
E2: Shipping=s= | F2: 0.5
E3: The market signal demands are as follows
G6: Pre Season initial order Q0 cost c0= | H6: 3
G7: In season Expedited top up order Q1(S) cost c1= | H7: 3.6
G8: Per order cost= | H8: 20 | I8: (assuming this for both pre season and In season)
G9: Sale price= | H9: 5 | I9: (assumption)
A10: (a) | D10: Now we order Q0 and then Q1. Let expected Sale be E(S)
F11: E[Revenue] | G11: Cost Var | H11: E[Salvage Val] | I11: E[Shipping cost] | K11: Per order cost | M11: E[Revenue]
F12: a | G12: b | H12: c | I12: d | K12: e | M12: a+c-b-d-e
C13: Dual order | D13: If E(S)<=Q0 | F13: E(S)*5 | G13: [Q0*3+Q1*3.6] | H13: [Q0-E(S)]*3*.5+Q1*3.6*.5 | I13: [Q0+Q1-E(S)]*0.5 | K13: 20*2 | M13: E(S)*5+{[Q0-E(S)]*3*.5+Q1*3.6*.5}-{[Q0*3+Q1*3.6]}-{[Q0+Q1-E(S)]*0.5}-20*2
C14: Dual order | D14: If Q0 <=E(S)<=Q1+Q0 | F14: E(S)*5 | G14: [Q0*3+Q1*3.6] | H14: [Q0+Q1-E(S)]*3.6*.5 | I14: [Q0+Q1-E(S)]*0.5 | K14: 20*2 | M14: E(S)*5+{[Q0+Q1-E(S)]*3.6*.5}-{[Q0*3+Q1*3.6]}-{[Q0+Q1-E(S)]*0.5}-20*2
C15: Single order | D15: If E(S)<=Q0 | F15: E(S)*5 | G15: Q0*3 | H15: [Q0-E(S)]*3*.5 | I15: [Q0-E(S)]*0.5 | K15: 20 | M15: E(S)*5+{[Q0-E(S)]*3*.5}-Q0*3-{[Q0-E(S)]*0.5}-20
C16: Single order | D16: If E(S)>Q0 | F16: Q0*5 | G16: Q0*3 | H16: 0 | I16: 0 | K16: 20 | M16: Q0*(5-3)-20
A18: (b) | D18: There are two ways to manager this, eigher have just a single pre-season order or have a pre season and then in season order
D19: Lets make the payoff table. The states of nature are D⏐S=High and D⏐S=Low
D20: Decision taken are Ordering optimal quantity basis S=High or S=Low at the beginning with no top up or order S=Low optimal with a top up to match S=High
D21: At pre season cost of $3.00
D22: For D⏐S=High single order
F23: co= 3-0.5*3+.5= | G23: =3-0.5*3+0.5 -> 2
F24: cu=5-3= | G24: =5-3 -> 2
F25: P(D≤Q0)=cu/(cu+co)= | G25: =G23/(G23+G24) -> 0.5
G26: =G25*(420-240)+240 -> 330
D28: for D⏐S=Low single order
F29: co= 3-0.5*3+.5= | G29: =3-0.5*3+0.5 -> 2
F30: cu=5-3= | G30: =5-3 -> 2
F31: P(D≤Q0)=cu/(cu+co)= | G31: =G29/(G29+G30) -> 0.5
G32: =G31*(260-120)+120 -> 190
D34: for both pre and in season ordering, the pre order could be placed till Q0/low or Q0/high and then basis high signal, place the next order to add Q1
D35: This looks like a quantity discount problem except the inverse since at higher quantity, the cost is going up. So we can use a similar approach
D36: Lets find Q2/high =Q1+Q0 | G36: (Q0 can be Q0/high or Q0/low)
F37: co= 3.6-0.5*3.6+.5= | G37: =3.6-0.5*3.6+0.5 -> 2.3
F38: cu=5-3.6= | G38: =5-3.6 -> 1.4
F39: P(D≤Q0)=cu/(cu+co)= | G39: =G37/(G37+G38) -> 0.62162162
G40: =G39*(420-240)+240 -> 351.89189
D42: Lets find Q2/low =Q1+Q0
F43: co= 3.6-0.5*3.6+.5= | G43: =3.6-0.5*3.6+0.5 -> 2.3
F44: cu=5-3.6= | G44: =5-3.6 -> 1.4
F45: P(D≤Q0)=cu/(cu+co)= | G45: =G43/(G43+G44) -> 0.62162162
G46: =G45*(260-120)+120 -> 207.02703
...
