Workbook

Sheet 1and2
B2: 1 week of sale
C3: Uniform distribution | D3: 120 | E3: 420
C4: Expected sale= | D4: =AVERAGE(D3:E3) -> 270
C6: Cost=c= | D6: 3
C7: Selling price=p= | D7: $5 or $6
C8: Refund fraction= | D8: 0.5 | E8: [0.25-0.75 scenarios]
C9: Return shipping= | D9: 0.5 | E9: per unit
C10: K= | D10: 20 | E10: per order
C11: Prize value= | D11: 40000
A12: 1 | C12: Suppose selling price is $5. So Cost of Underage=5-3=$2; Cost of overage=3+0.5-3*0.5=2. So the right balance would be at the mid point and hence 270.
C13: This is because for every unit extra we don’t sell, it would cost $2 and every unit shortage we have, we loos $2 as well.
C14: We need to find the spot where P(D>=Q)=P(D<=Q)=Mean demand for the uniform distribution and in this case it is 270
C15: At $6 selling price, the custo of Underage=6-3=$3 while the cost of overage remains the same at $2. So it hurts to loose sales than have overages.
C16: So in this case, the tendence would be to keep higher stock than mid point and hence more than 270
A18: 2 | C18: At $5 selling price
B19: Co= | C19: 3-0.5*3+.5= | D19: =3-0.5*3+0.5 -> 2
B20: Cu= | C20: 5-3= | D20: =5-3 -> 2
B21: F(X*)= | C21: Cu/(Cu+Co)= | D21: =D20/(D20+D19) -> 0.5
B23: X*$5,0.5= | C23: =D21*($E$3-$D$3)+$D$3 -> 270 | D23: Expected Sales= | K23: =(270^2-120^2)/(2*300)+((420-270)*270)/300 -> 232.5
D24: Expected left over= | F24: =C23-K23 -> 37.5 | G24: a. | H24: Expected revenue= | J24: =$K23*5 -> 1162.5
G25: b. | H25: Salvage value of left over= | K25: =F24*$D$6*$D$8 -> 56.25
G26: c. | H26: Shipping cost= | J26: =F24*$D$9*-1 -> -18.75
G27: d. | H27: Ordering cost= | J27: =$D$10*-1 -> -20
G28: e. | H28: Variable buying cost= | J28: =C23*D6*-1 -> -810
I29: Expected Profit= | J29: a+b+c+d+e
I30: = | J30: =J27+J26+K25+J24+J28 -> 370
B32: Limitation of using uniform demand assumption:
B35: at $6 selling price
B36: Co= | C36: 3-0.5*3+.5= | D36: =3-0.5*3+0.5 -> 2
B37: Cu= | C37: 6-3= | D37: =6-3 -> 3
B38: F(X*)= | C38: Cu/(Cu+Co)= | D38: =D37/(D37+D36) -> 0.6
B40: X*$6,0.5= | C40: =D38*($E$3-$D$3)+$D$3 -> 300 | D40: Expected Sales= | K40: =(300^2-120^2)/(2*300)+((420-300)*300)/300 -> 246
D41: Expected left over= | F41: =C40-K40 -> 54 | G41: a. | H41: Expected revenue= | J41: =$K40*6 -> 1476
G42: b. | H42: Salvage value of left over= | K42: =F41*$D$6*$D$8 -> 81
G43: c. | H43: Shipping cost= | J43: =F41*$D$9*-1 -> -27
G44: d. | H44: Ordering cost= | J44: =$D$10*-1 -> -20
G45: e. | H45: Variable buying cost= | J45: =C40*D6*-1 -> -900
I46: Expected Profit= | J46: a+b+c+d+e
I47: = | J47: =J44+J43+K42+J41+J45 -> 610

Sheet 3
B2: 1 week of sale
C3: Uniform dist | D3: 120 | E3: 420
C4: Expected sale= | D4: =AVERAGE(D3:E3) -> 270
C6: Cost=c= | D6: 3
C7: Selling price=p= | D7: $5 or $6
C8: Refund fraction= | D8: 0.5 | E8: [0.25-0.75 scenarios]
C9: Return shipping= | D9: 0.5 | E9: per unit
C10: K= | D10: 20 | E10: per order
C11: Prize value= | D11: 40000
B14: at $5 selling price | D14: at 0.25 refund | F14: at 0.75 refund
B15: Co= | C15: 3-0.25*3+.5= | D15: =3-0.25*3+0.5 -> 2.75 | E15: 3-0.75*3+.5= | F15: =3-0.75*3+0.5 -> 1.25
B16: Cu= | C16: 5-3= | D16: =5-3 -> 2 | F16: =5-3 -> 2
B17: F(X*)= | C17: Cu/(Cu+Co)= | D17: =D16/(D16+D15) -> 0.42105263 | F17: =F16/(F16+F15) -> 0.61538462
D19: =D17*($E$3-$D$3)+$D$3 -> 246.31579 | F19: =F17*($E$3-$D$3)+$D$3 -> 304.61538
B20: at $6 selling price
B21: Co= | C21: 3-0.25*3+.5= | D21: =3-0.25*3+0.5 -> 2.75 | E21: 3-0.75*3+.5= | F21: =3-0.75*3+0.5 -> 1.25
B22: Cu= | C22: 6-3= | D22: =6-3 -> 3 | F22: =6-3 -> 3
B23: F(X*)= | C23: Cu/(Cu+Co)= | D23: =D22/(D22+D21) -> 0.52173913 | F23: =F22/(F22+F21) -> 0.70588235
B25: X*$6,0.25= | D25: =D23*(E3-D3)+D3 -> 276.52174 | F25: =F23*($E$3-$D$3)+$D$3 -> 331.76471

Sheet 4
B2: 1 week of sale | I2: 1 week of sale
C3: Uniform dist | D3: 120 | E3: 420 | J3: Uniform dist | K3: 120 | L3: 420
C4: Expected sale= | D4: =AVERAGE(D3:E3) -> 270 | J4: Expected sale= | K4: =AVERAGE(K3:L3) -> 270
C6: Cost=c= | D6: 3 | J6: Cost=c= | K6: 3
C7: Selling price=p= | D7: $5 or $6 | J7: Selling price=p= | K7: $5 or $6
C8: Refund fraction= | D8: 0.5 | E8: [0.25-0.75 scenarios] | J8: Refund fraction= | K8: 0.5 | L8: [0.25-0.75 scenarios]
C9: Return shipping= | D9: 0.5 | E9: per unit | J9: Return shipping= | K9: 0.5 | L9: per unit
C10: K= | D10: 20 | E10: per order | J10: K= | K10: 20 | L10: per order
C11: Prize value= | D11: 40000 | J11: Prize value= | K11: 40000
B20: at $6 selling price | D20: at 0.5 refund | I20: at $5 selling price | K20: at 0.5 refund
B21: Co= | C21: 3-0.5*3+.5= | D21: =3-0.5*3+0.5 -> 2 | I21: Co= | J21: 3-0.5*3+.5= | K21: =3-0.5*3+0.5 -> 2
B22: Cu= | C22: 6-3= | D22: =6-3 -> 3 | I22: Cu= | J22: 5-3= | K22: =5-3 -> 2
B23: F(X*)= | C23: Cu/(Cu+Co)= | D23: =D22/(D22+D21) -> 0.6 | I23: F(X*)= | J23: Cu/(Cu+Co)= | K23: =K22/(K22+K21) -> 0.5
B25: X*= | D25: =D23*(E3-D3)+D3 -> 300 | I25: X*= | K25: =K23*(L3-K3)+K3 -> 270
B26: Expected Sales= | G26: =(300^2-120^2)/(2*300)+((420-300)*300)/300 -> 246 | I26: Expected Sales= | N26: =(270^2-120^2)/(2*300)+((420-270)*270)/300 -> 232.5
B27: Expected left over= | C27: =D25-G26 -> 54 | D27: a. | E27: Expected revenue= | G27: =$G26*6 -> 1476 | I27: Expected left over= | J27: =K25-N26 -> 37.5 | K27: a. | L27: Expected revenue= | N27: =$N26*5 -> 1162.5
D28: b. | E28: Salvage value of left over= | G28: =C27*$D$6*$D$8 -> 81 | K28: b. | L28: Salvage value of left over= | N28: =J27*$D$6*$D$8 -> 56.25
D29: c. | E29: Shipping cost= | G29: =C27*$D$9*-1 -> -27 | K29: c. | L29: Shipping cost= | N29: =J27*$D$9*-1 -> -18.75
D30: d. | E30: Ordering cost= | G30: =$D$10*-1 -> -20 | K30: d. | L30: Ordering cost= | N30: =$D$10*-1 -> -20
D31: e. | E31: Variable buying cost= | G31: =-1*D25*D6 -> -900 | K31: e. | L31: Variable buying cost= | N31: =-1*K25*K6 -> -810
F32: Expected Profit= | G32: a+b+c+d+e | M32: Expected Profit= | N32: a+b+c+d+e
F33: = | G33: =G30+G29+G28+G27+G31 -> 610 | M33: = | N33: =N30+N29+N28+N27+N31 -> 370
A36: Would would happen if raising prices changes demand?

Sheet 5
B2: 1 week of sale
C3: Uniform dist | D3: 120 | E3: 420
C4: Expected sale= | D4: =AVERAGE(D3:E3) -> 270 | I4: S.no | J4: Demand | K4: Units sold | L4: Left over units | M4: Revenue | N4: Setup cost | O4: Cost - Var | P4: Cost-shipping | Q4: Refund | R4: Net Profit | S4: count of loss
I5: 1 | J5: =RANDBETWEEN(120,420) -> 127 | K5: =IF(J5>=$D$18,$D$18,J5) -> 127 | L5: =$D$18-K5 -> 143 | M5: =K5*5 -> 635 | N5: =-$D$10 -> -20 | O5: =-$D$6*$D$18 -> -810 | P5: =-L5*$D$9 -> -71.5 | Q5: =L5*($D$6*$D$8) -> 214.5 | R5: =SUM(M5:Q5) -> -52 | S5: =IF(R5<0,1,0) -> 1
C6: Cost=c= | D6: 3 | I6: =I5+1 -> 2 | J6: =RANDBETWEEN(120,420) -> 417 | K6: =IF(J6>=$D$18,$D$18,J6) -> 270 | L6: =$D$18-K6 -> 0 | M6: =K6*5 -> 1350 | N6: =-$D$10 -> -20 | O6: =-$D$6*$D$18 -> -810 | P6: =-L6*$D$9 -> 0 | Q6: =L6*($D$6*$D$8) -> 0 | R6: =SUM(M6:Q6) -> 520 | S6: =IF(R6<0,1,0) -> 0
C7: Selling price=p= | D7: $5 or $6 | I7: =I6+1 -> 3 | J7: =RANDBETWEEN(120,420) -> 274 | K7: =IF(J7>=$D$18,$D$18,J7) -> 270 | L7: =$D$18-K7 -> 0 | M7: =K7*5 -> 1350 | N7: =-$D$10 -> -20 | O7: =-$D$6*$D$18 -> -810 | P7: =-L7*$D$9 -> 0 | Q7: =L7*($D$6*$D$8) -> 0 | R7: =SUM(M7:Q7) -> 520 | S7: =IF(R7<0,1,0) -> 0
C8: Refund fraction= | D8: 0.5 | E8: [0.25-0.75 scenarios] | I8: =I7+1 -> 4 | J8: =RANDBETWEEN(120,420) -> 410 | K8: =IF(J8>=$D$18,$D$18,J8) -> 270 | L8: =$D$18-K8 -> 0 | M8: =K8*5 -> 1350 | N8: =-$D$10 -> -20 | O8: =-$D$6*$D$18 -> -810 | P8: =-L8*$D$9 -> 0 | Q8: =L8*($D$6*$D$8) -> 0 | R8: =SUM(M8:Q8) -> 520 | S8: =IF(R8<0,1,0) -> 0
C9: Return shipping= | D9: 0.5 | E9: per unit | I9: =I8+1 -> 5 | J9: =RANDBETWEEN(120,420) -> 305 | K9: =IF(J9>=$D$18,$D$18,J9) -> 270 | L9: =$D$18-K9 -> 0 | M9: =K9*5 -> 1350 | N9: =-$D$10 -> -20 | O9: =-$D$6*$D$18 -> -810 | P9: =-L9*$D$9 -> 0 | Q9: =L9*($D$6*$D$8) -> 0 | R9: =SUM(M9:Q9) -> 520 | S9: =IF(R9<0,1,0) -> 0
C10: K= | D10: 20 | E10: per order | I10: =I9+1 -> 6 | J10: =RANDBETWEEN(120,420) -> 201 | K10: =IF(J10>=$D$18,$D$18,J10) -> 201 | L10: =$D$18-K10 -> 69 | M10: =K10*5 -> 1005 | N10: =-$D$10 -> -20 | O10: =-$D$6*$D$18 -> -810 | P10: =-L10*$D$9 -> -34.5 | Q10: =L10*($D$6*$D$8) -> 103.5 | R10: =SUM(M10:Q10) -> 244 | S10: =IF(R10<0,1,0) -> 0
C11: Prize value= | D11: 40000 | I11: =I10+1 -> 7 | J11: =RANDBETWEEN(120,420) -> 356 | K11: =IF(J11>=$D$18,$D$18,J11) -> 270 | L11: =$D$18-K11 -> 0 | M11: =K11*5 -> 1350 | N11: =-$D$10 -> -20 | O11: =-$D$6*$D$18 -> -810 | P11: =-L11*$D$9 -> 0 | Q11: =L11*($D$6*$D$8) -> 0 | R11: =SUM(M11:Q11) -> 520 | S11: =IF(R11<0,1,0) -> 0
I12: =I11+1 -> 8 | J12: =RANDBETWEEN(120,420) -> 242 | K12: =IF(J12>=$D$18,$D$18,J12) -> 242 | L12: =$D$18-K12 -> 28 | M12: =K12*5 -> 1210 | N12: =-$D$10 -> -20 | O12: =-$D$6*$D$18 -> -810 | P12: =-L12*$D$9 -> -14 | Q12: =L12*($D$6*$D$8) -> 42 | R12: =SUM(M12:Q12) -> 408 | S12: =IF(R12<0,1,0) -> 0
B13: at $5 selling price | D13: at 0.5 refund | I13: =I12+1 -> 9 | J13: =RANDBETWEEN(120,420) -> 293 | K13: =IF(J13>=$D$18,$D$18,J13) -> 270 | L13: =$D$18-K13 -> 0 | M13: =K13*5 -> 1350 | N13: =-$D$10 -> -20 | O13: =-$D$6*$D$18 -> -810 | P13: =-L13*$D$9 -> 0 | Q13: =L13*($D$6*$D$8) -> 0 | R13: =SUM(M13:Q13) -> 520 | S13: =IF(R13<0,1,0) -> 0
B14: Co= | C14: 3-0.5*3+.5= | D14: =3-0.5*3+0.5 -> 2 | I14: =I13+1 -> 10 | J14: =RANDBETWEEN(120,420) -> 273 | K14: =IF(J14>=$D$18,$D$18,J14) -> 270 | L14: =$D$18-K14 -> 0 | M14: =K14*5 -> 1350 | N14: =-$D$10 -> -20 | O14: =-$D$6*$D$18 -> -810 | P14: =-L14*$D$9 -> 0 | Q14: =L14*($D$6*$D$8) -> 0 | R14: =SUM(M14:Q14) -> 520 | S14: =IF(R14<0,1,0) -> 0
B15: Cu= | C15: 5-3= | D15: =5-3 -> 2 | I15: =I14+1 -> 11 | J15: =RANDBETWEEN(120,420) -> 322 | K15: =IF(J15>=$D$18,$D$18,J15) -> 270 | L15: =$D$18-K15 -> 0 | M15: =K15*5 -> 1350 | N15: =-$D$10 -> -20 | O15: =-$D$6*$D$18 -> -810 | P15: =-L15*$D$9 -> 0 | Q15: =L15*($D$6*$D$8) -> 0 | R15: =SUM(M15:Q15) -> 520 | S15: =IF(R15<0,1,0) -> 0
B16: F(X*)= | C16: Cu/(Cu+Co)= | D16: =D15/(D15+D14) -> 0.5 | I16: =I15+1 -> 12 | J16: =RANDBETWEEN(120,420) -> 379 | K16: =IF(J16>=$D$18,$D$18,J16) -> 270 | L16: =$D$18-K16 -> 0 | M16: =K16*5 -> 1350 | N16: =-$D$10 -> -20 | O16: =-$D$6*$D$18 -> -810 | P16: =-L16*$D$9 -> 0 | Q16: =L16*($D$6*$D$8) -> 0 | R16: =SUM(M16:Q16) -> 520 | S16: =IF(R16<0,1,0) -> 0
I17: =I16+1 -> 13 | J17: =RANDBETWEEN(120,420) -> 140 | K17: =IF(J17>=$D$18,$D$18,J17) -> 140 | L17: =$D$18-K17 -> 130 | M17: =K17*5 -> 700 | N17: =-$D$10 -> -20 | O17: =-$D$6*$D$18 -> -810 | P17: =-L17*$D$9 -> -65 | Q17: =L17*($D$6*$D$8) -> 195 | R17: =SUM(M17:Q17) -> 0 | S17: =IF(R17<0,1,0) -> 0
B18: X*= | D18: =D16*(E3-D3)+D3 -> 270 | I18: =I17+1 -> 14 | J18: =RANDBETWEEN(120,420) -> 184 | K18: =IF(J18>=$D$18,$D$18,J18) -> 184 | L18: =$D$18-K18 -> 86 | M18: =K18*5 -> 920 | N18: =-$D$10 -> -20 | O18: =-$D$6*$D$18 -> -810 | P18: =-L18*$D$9 -> -43 | Q18: =L18*($D$6*$D$8) -> 129 | R18: =SUM(M18:Q18) -> 176 | S18: =IF(R18<0,1,0) -> 0
I19: =I18+1 -> 15 | J19: =RANDBETWEEN(120,420) -> 174 | K19: =IF(J19>=$D$18,$D$18,J19) -> 174 | L19: =$D$18-K19 -> 96 | M19: =K19*5 -> 870 | N19: =-$D$10 -> -20 | O19: =-$D$6*$D$18 -> -810 | P19: =-L19*$D$9 -> -48 | Q19: =L19*($D$6*$D$8) -> 144 | R19: =SUM(M19:Q19) -> 136 | S19: =IF(R19<0,1,0) -> 0
I20: =I19+1 -> 16 | J20: =RANDBETWEEN(120,420) -> 273 | K20: =IF(J20>=$D$18,$D$18,J20) -> 270 | L20: =$D$18-K20 -> 0 | M20: =K20*5 -> 1350 | N20: =-$D$10 -> -20 | O20: =-$D$6*$D$18 -> -810 | P20: =-L20*$D$9 -> 0 | Q20: =L20*($D$6*$D$8) -> 0 | R20: =SUM(M20:Q20) -> 520 | S20: =IF(R20<0,1,0) -> 0
I21: =I20+1 -> 17 | J21: =RANDBETWEEN(120,420) -> 329 | K21: =IF(J21>=$D$18,$D$18,J21) -> 270 | L21: =$D$18-K21 -> 0 | M21: =K21*5 -> 1350 | N21: =-$D$10 -> -20 | O21: =-$D$6*$D$18 -> -810 | P21: =-L21*$D$9 -> 0 | Q21: =L21*($D$6*$D$8) -> 0 | R21: =SUM(M21:Q21) -> 520 | S21: =IF(R21<0,1,0) -> 0
I22: =I21+1 -> 18 | J22: =RANDBETWEEN(120,420) -> 256 | K22: =IF(J22>=$D$18,$D$18,J22) -> 256 | L22: =$D$18-K22 -> 14 | M22: =K22*5 -> 1280 | N22: =-$D$10 -> -20 | O22: =-$D$6*$D$18 -> -810 | P22: =-L22*$D$9 -> -7 | Q22: =L22*($D$6*$D$8) -> 21 | R22: =SUM(M22:Q22) -> 464 | S22: =IF(R22<0,1,0) -> 0
I23: =I22+1 -> 19 | J23: =RANDBETWEEN(120,420) -> 175 | K23: =IF(J23>=$D$18,$D$18,J23) -> 175 | L23: =$D$18-K23 -> 95 | M23: =K23*5 -> 875 | N23: =-$D$10 -> -20 | O23: =-$D$6*$D$18 -> -810 | P23: =-L23*$D$9 -> -47.5 | Q23: =L23*($D$6*$D$8) -> 142.5 | R23: =SUM(M23:Q23) -> 140 | S23: =IF(R23<0,1,0) -> 0
I24: =I23+1 -> 20 | J24: =RANDBETWEEN(120,420) -> 261 | K24: =IF(J24>=$D$18,$D$18,J24) -> 261 | L24: =$D$18-K24 -> 9 | M24: =K24*5 -> 1305 | N24: =-$D$10 -> -20 | O24: =-$D$6*$D$18 -> -810 | P24: =-L24*$D$9 -> -4.5 | Q24: =L24*($D$6*$D$8) -> 13.5 | R24: =SUM(M24:Q24) -> 484 | S24: =IF(R24<0,1,0) -> 0
I25: =I24+1 -> 21 | J25: =RANDBETWEEN(120,420) -> 143 | K25: =IF(J25>=$D$18,$D$18,J25) -> 143 | L25: =$D$18-K25 -> 127 | M25: =K25*5 -> 715 | N25: =-$D$10 -> -20 | O25: =-$D$6*$D$18 -> -810 | P25: =-L25*$D$9 -> -63.5 | Q25: =L25*($D$6*$D$8) -> 190.5 | R25: =SUM(M25:Q25) -> 12 | S25: =IF(R25<0,1,0) -> 0
I26: =I25+1 -> 22 | J26: =RANDBETWEEN(120,420) -> 185 | K26: =IF(J26>=$D$18,$D$18,J26) -> 185 | L26: =$D$18-K26 -> 85 | M26: =K26*5 -> 925 | N26: =-$D$10 -> -20 | O26: =-$D$6*$D$18 -> -810 | P26: =-L26*$D$9 -> -42.5 | Q26: =L26*($D$6*$D$8) -> 127.5 | R26: =SUM(M26:Q26) -> 180 | S26: =IF(R26<0,1,0) -> 0
I27: =I26+1 -> 23 | J27: =RANDBETWEEN(120,420) -> 180 | K27: =IF(J27>=$D$18,$D$18,J27) -> 180 | L27: =$D$18-K27 -> 90 | M27: =K27*5 -> 900 | N27: =-$D$10 -> -20 | O27: =-$D$6*$D$18 -> -810 | P27: =-L27*$D$9 -> -45 | Q27: =L27*($D$6*$D$8) -> 135 | R27: =SUM(M27:Q27) -> 160 | S27: =IF(R27<0,1,0) -> 0
I28: =I27+1 -> 24 | J28: =RANDBETWEEN(120,420) -> 314 | K28: =IF(J28>=$D$18,$D$18,J28) -> 270 | L28: =$D$18-K28 -> 0 | M28: =K28*5 -> 1350 | N28: =-$D$10 -> -20 | O28: =-$D$6*$D$18 -> -810 | P28: =-L28*$D$9 -> 0 | Q28: =L28*($D$6*$D$8) -> 0 | R28: =SUM(M28:Q28) -> 520 | S28: =IF(R28<0,1,0) -> 0
I29: =I28+1 -> 25 | J29: =RANDBETWEEN(120,420) -> 397 | K29: =IF(J29>=$D$18,$D$18,J29) -> 270 | L29: =$D$18-K29 -> 0 | M29: =K29*5 -> 1350 | N29: =-$D$10 -> -20 | O29: =-$D$6*$D$18 -> -810 | P29: =-L29*$D$9 -> 0 | Q29: =L29*($D$6*$D$8) -> 0 | R29: =SUM(M29:Q29) -> 520 | S29: =IF(R29<0,1,0) -> 0
I30: =I29+1 -> 26 | J30: =RANDBETWEEN(120,420) -> 271 | K30: =IF(J30>=$D$18,$D$18,J30) -> 270 | L30: =$D$18-K30 -> 0 | M30: =K30*5 -> 1350 | N30: =-$D$10 -> -20 | O30: =-$D$6*$D$18 -> -810 | P30: =-L30*$D$9 -> 0 | Q30: =L30*($D$6*$D$8) -> 0 | R30: =SUM(M30:Q30) -> 520 | S30: =IF(R30<0,1,0) -> 0
... I504: =I503+1 -> 500 | J504: =RANDBETWEEN(120,420) -> 325 | K504: =IF(J504>=$D$18,$D$18,J504) -> 270 | L504: =$D$18-K504 -> 0 | M504: =K504*5 -> 1350 | N504: =-$D$10 -> -20 | O504: =-$D$6*$D$18 -> -810 | P504: =-L504*$D$9 -> 0 | Q504: =L504*($D$6*$D$8) -> 0 | R504: =SUM(M504:Q504) -> 520 | S504: =IF(R504<0,1,0) -> 0
J505: =AVERAGE(J5:J504) -> 272.436 | Q505: Avg Profit[500 simulation] | R505: =AVERAGE(R5:R504) -> 374.336
Q506: E[Profit] | R506: ='4'!N33 -> 370
Q507: Std Dev of Profit | R507: =STDEV(R5:R504) -> 193.57284
Q508: No. of instance of loss | R508: =SUM(S5:S504) -> 33
Q509: P(loss)= | R509: =R508/500 -> 0.066

Sheet Sheet2
J19: 94.2 | K19: 0.15 | L19: =K19*J19 -> 14.13
J20: =39.5/40*100 -> 98.75 | K20: 0.1 | L20: =K20*J20 -> 9.875
J21: 84.5 | K21: 0.5 | L21: =K21*J21 -> 42.25
J22: 100 | K22: 0.25 | L22: =K22*J22 -> 25
L23: =SUM(L19:L22) -> 91.255

Sheet 6
N3: Leisure Limited awards $40,000 to the stand with highest sales. SparkFire estimates a
B4: a) | C4: From 1,2,3 we have below X* at various Selling prices and fraction as refund | N4: 5% chance of winning if actual sales are ≥400 units. Other states use 3% if actual sales
E5: X* at various fractions of refund | N5: ≥380 or 7% if actual sales ≥420 are mentioned as context.
E6: 0.25 | F6: 0.5 | G6: 0.75 | N6: (a) Modify your profit model to account for the possibility of awards.
C7: Sellling Price | D7: 5 | E7: ='3'!D19 -> 246.31579 | F7: ='1and2'!C23 -> 270 | G7: ='3'!F19 -> 304.61538 | N7: (b) Find the new quantity Q∗∗ that maximizes total expected returns.
D8: 6 | E8: ='3'!D25 -> 276.52174 | F8: ='1and2'!C40 -> 300 | G8: ='3'!F25 -> 331.76471 | N8: (c) Compare Q∗∗ to Q∗ (from Part 2) and discuss how this incentive scheme encourages
N9: risk-seeking or risk-averse behavior.
C10: Now below are the changes of winning
D12: Sales | E12: Probability of winning | G12: Correspond X*
D13: >=400 | E13: 0.05 | G13: Nil
D14: >=380 | E14: 0.03 | G14: Nil
D15: >=420 | E15: 0.07 | G15: Nil
C17: Lets find X* with below add ons
C18: 1. Assuming sales >=400, then Addional revenue=40000*.05= | H18: =40000*0.05 -> 2000 | I18: overall; So per unit on 400 (minimum qty)= | M18: =2000/400 -> 5 | N18: $per unit
C19: So Cu=5+5-3= | E19: =2+5 -> 7
C20: Co=3-0.5*3+.5= | E20: =3-0.5*3+0.5 -> 2
C21: So F(X*)= | E21: =E19/(E20+E19) -> 0.77777778
C22: X*= | E22: =E21*(420-120)+120 -> 353.33333 | G22: at 0.5 refund fraction
C24: 1. Assuming X* >=380, then Addional revenue=40000*.03= | H24: =40000*0.03 -> 1200 | I24: overall; So per unit on 380 (minimum qty)= | M24: =1200/380 -> 3.1578947 | N24: $per unit
C25: So Cu=5+3.2-3= | E25: =2+3.2 -> 5.2
C26: Co=3-0.5*3+.5= | E26: =3-0.5*3+0.5 -> 2
C27: So F(X*)= | E27: =E25/(E26+E25) -> 0.72222222
C28: X*= | E28: =E27*(420-120)+120 -> 336.66667 | G28: at 0.5 refund fraction
C31: To sell 400 we need atleast 400. suppose we stock 400 units
C32: So demand could be split as either <= 400, or >400 | L32: Probabilities | N32: D< | O32: 380 | P32: =(O32-120)/(420-120) -> 0.86666667 | Q32: 380 | R32: <=D<= | S32: 400 | T32: =(S32-120)/(420-120)-P32 -> 0.066666667 | U32: D< | V32: 400 | W32: =(V32-120)/(420-120) -> 0.93333333 | X32: 400 | Y32: <=D<= | Z32: 420 | AA32: =(Z32-120)/(420-120)-W32 -> 0.066666667 | AB32: <=D | AC32: 420 | AD32: 0
C33: Expected sale when demand<400 is | H33: =(400^2-120^2)/(2*300) -> 242.66667 | L33: Exp Sale | O33: =(O32^2-120^2)/(2*300) -> 216.66667 | V33: =(V32^2-120^2)/(2*300) -> 242.66667 | AC33: =(AC32^2-120^2)/(2*300) -> 270
C34: Expected Profit when Demand<400= | G34: =H33*5+(400-H33)*0.5*3-(400-H33)*0.5-400*3+H36*E14*40000 -> 250.66667 | H34: (without set up cost) | L34: Exp left | O34: =O32-O33 -> 163.33333 | V34: =V32-V33 -> 157.33333 | AC34: =AC32-AC33 -> 150
C35: Probability Demand>=380 but less than 400=P(D<=400)-p(D<=380=(400-120)/(420-120)-(380-120)/(420-120) | L35: Exp profit | O35: =O33*5+O34*0.5*3-O32*3-O34*0.5 -> 106.66667 | V35: =V33*5+V34*0.5*3-V32*3-V34*0.5 -> 170.66667 | AC35: =AC33*5+AC34*0.5*3-AC32*3-AC34*0.5 -> 240
G36: = | H36: =(400-120)/(420-120)-(380-120)/(420-120) -> 0.066666667
C37: Probability Demand>400=1-P(D<=400)= | G37: =1-(400-120)/(420-120) -> 0.066666667 | L37: Sales | M37: Probability of winning
C38: for Demand>400, sale= | E38: 400 | L38: >=400 | M38: 0.05
C39: So profit without winning prize= | F39: =400*5-400*3 -> 800 | G39: for Demand>=400 | L39: >=380 | M39: 0.03
C40: Profit with winning prize= | F40: =800+40000 -> 40800 | L40: >=420 | M40: 0.07
C41: Expected profit when Demand>=400= | G41: =G37*(F39*(1-E13)+F40*E13) -> 186.66667
M43: Qty | N43: Expected Qty | O43: Exp leftover | P43: Reg. exp profit | R43: Profit with reward | S43: Optimal profit w/o reward | V43: Qty | W43: Exp profit | X43: Expected sale | Y43: Exp left over
C44: Total profit= | E44: =G41+G34-20 -> 417.33333 | G44: (inclusive of ordering cost) | M44: =M45-1 -> 372 | N44: =(M44^2-120^2)/(2*300)+M44*(420-M44)/300 -> 266.16 | O44: =M44-N44 -> 105.84 | P44: =N44*5+O44*0.5*3-O44*0.5-M44*3-20 -> 300.64 | R44: =P44 -> 300.64 | S44: =S52 -> 370 | V44: 120 | W44: =X44*5+Y44*0.5*3-Y44*0.5-V44*3-20 -> 220 | X44: =(V44^2-120^2)/(2*300)+V44*(420-V44)/300 -> 120 | Y44: =V44-X44 -> 0
C45: At EOQ in part 2 we saw the profit was= | F45: ='1and2'!J30 -> 370 | G45: which is lesser than with the reward | M45: =M46-1 -> 373 | N45: =(M45^2-120^2)/(2*300)+M45*(420-M45)/300 -> 266.31833 | O45: =M45-N45 -> 106.68167 | P45: =N45*5+O45*0.5*3-O45*0.5-M45*3-20 -> 299.27333 | R45: =P45 -> 299.27333 | S45: =S53 -> 370 | V45: =V44+1 -> 121 | W45: =X45*5+Y45*0.5*3-Y45*0.5-V45*3-20 -> 221.99333 | X45: =(V45^2-120^2)/(2*300)+V45*(420-V45)/300 -> 120.99833 | Y45: =V45-X45 -> 0.0016666667
M46: =M47-1 -> 374 | N46: =(M46^2-120^2)/(2*300)+M46*(420-M46)/300 -> 266.47333 | O46: =M46-N46 -> 107.52667 | P46: =N46*5+O46*0.5*3-O46*0.5-M46*3-20 -> 297.89333 | R46: =P46 -> 297.89333 | S46: =S54 -> 370 | V46: =V45+1 -> 122 | W46: =X46*5+Y46*0.5*3-Y46*0.5-V46*3-20 -> 223.97333 | X46: =(V46^2-120^2)/(2*300)+V46*(420-V46)/300 -> 121.99333 | Y46: =V46-X46 -> 0.0066666667
C47: Now suppose we had inventory at 380 units | M47: =M48-1 -> 375 | N47: =(M47^2-120^2)/(2*300)+M47*(420-M47)/300 -> 266.625 | O47: =M47-N47 -> 108.375 | P47: =N47*5+O47*0.5*3-O47*0.5-M47*3-20 -> 296.5 | R47: =P47 -> 296.5 | S47: =S55 -> 370 | V47: =V46+1 -> 123 | W47: =X47*5+Y47*0.5*3-Y47*0.5-V47*3-20 -> 225.94 | X47: =(V47^2-120^2)/(2*300)+V47*(420-V47)/300 -> 122.985 | Y47: =V47-X47 -> 0.015
C48: Expected sale when demand<380 is | H48: =(380^2-120^2)/(2*300) -> 216.66667 | M48: =M49-1 -> 376 | N48: =(M48^2-120^2)/(2*300)+M48*(420-M48)/300 -> 266.77333 | O48: =M48-N48 -> 109.22667 | P48: =N48*5+O48*0.5*3-O48*0.5-M48*3-20 -> 295.09333 | R48: =P48 -> 295.09333 | S48: =S56 -> 370 | V48: =V47+1 -> 124 | W48: =X48*5+Y48*0.5*3-Y48*0.5-V48*3-20 -> 227.89333 | X48: =(V48^2-120^2)/(2*300)+V48*(420-V48)/300 -> 123.97333 | Y48: =V48-X48 -> 0.026666667
...

Sheet 7
E4: Optimal qty at unit cost | T4: Expected left over | U4: Salvage value | V4: Shipping cost | W4: Net Profit
B5: Order Qty | C5: Unit cost | E5: (@ $5 selling price) | G5: (@ $6 selling price) | I5: Comment | L5: Total cost at | M5: Cost Total | N5: Expected Sale qty
B6: 1-199 | C6: 3 | E6: ='1and2'!C23 -> 270 | G6: ='1and2'!C40 -> 300 | I6: Beyond order qty range for that cost | L6: 199 units= | M6: =(199*3+G25)*-1 -> -617 | S6: =(199^2-120^2)/(2*300)+((420-199)*199)/300 -> 188.59833 | T6: =199-S6 -> 10.401667 | U6: =T6*$G$23*C6 -> 15.6025 | V6: =T6*$G$24*-1 -> -5.2008333 | W6: =S6*$G$22+V6+U6+M6 -> 336.39333
B8: 200-399 | C8: 2.85 | E8: =F34 -> 278.28221 | I8: within the range so this should be ordered | L8: =TEXT(E8,"0.00") & " units" -> 278.28 units | M8: =(E8*C8+20)*-1 -> -813.10429 | S8: =(278.28^2-120^2)/(2*300)+((420-278.28)*278.28)/300 -> 236.52574 | T8: =278-S8 -> 41.474264 | U8: =T8*$G$23*C8 -> 59.100826 | V8: =T8*$G$24*-1 -> -20.737132 | W8: =S8*$G$22+V8+U8+M8 -> 407.88808
B10: 400+ | C10: 2.7 | E10: =L34 -> 286.26506 | I10: Below the range of 400 so we use 400 | L10: 400 | M10: =(E10*C10+20)*-1 -> -792.91566 | S10: =(400^2-120^2)/(2*300)+((420-400)*400)/300 -> 269.33333 | T10: =400-S10 -> 130.66667 | U10: =T10*$G$23*C10 -> 176.4 | V10: =T10*$G$24*-1 -> -65.333333 | W10: =S10*$G$22+V10+U10+M10 -> 664.81767
E17: 1 week of sale | K17: 1 week of sale
F18: Uniform dist | G18: 120 | H18: 420 | L18: Uniform dist | M18: 120 | N18: 420
F19: Expected sale= | G19: =AVERAGE(G18:H18) -> 270 | L19: Expected sale= | M19: =AVERAGE(M18:N18) -> 270
F21: Cost=c= | G21: =C8 -> 2.85 | L21: Cost=c= | M21: =C10 -> 2.7
F22: Selling price=p= | G22: 5 | L22: Selling price=p= | M22: 5
F23: Refund fraction= | G23: 0.5 | H23: [0.25-0.75 scenarios] | L23: Refund fraction= | M23: 0.5 | N23: [0.25-0.75 scenarios]
F24: Return shipping= | G24: 0.5 | H24: per unit | L24: Return shipping= | M24: 0.5 | N24: per unit
F25: K= | G25: 20 | H25: per order | L25: K= | M25: 20 | N25: per order
F26: Prize value= | G26: 40000 | L26: Prize value= | M26: 40000
E29: at $5 selling price | K29: at $5 selling price
E30: Co= | F30: 2.85-0.5*2.85+.5= | G30: =G21-0.5*G21+0.5 -> 1.925 | K30: Co= | L30: 2.85-0.5*2.85+.5= | M30: =M21-0.5*M21+0.5 -> 1.85
E31: Cu= | F31: 5-3= | G31: =5-G21 -> 2.15 | K31: Cu= | L31: 5-3= | M31: =5-M21 -> 2.3
E32: F(X*)= | F32: Cu/(Cu+Co)= | G32: =G31/(G31+G30) -> 0.52760736 | K32: F(X*)= | L32: Cu/(Cu+Co)= | M32: =M31/(M31+M30) -> 0.55421687
E34: X*$5,0.5= | F34: =G32*(420-120)+120 -> 278.28221 | K34: X*$5,0.5= | L34: =M32*(420-120)+120 -> 286.26506

Sheet 8
F1: f= | G1: 0.5 | H1: % of cost
F2: Shipping=s= | G2: 0.5
F3: The market signal demands are as follows
H6: Pre Season initial order Q0 cost c0= | I6: 3
H7: In season Expedited top up order Q1(S) cost c1= | I7: 3.6
H8: Per order cost= | I8: 20 | J8: (assuming this for both pre season and In season)
H9: Sale price= | I9: 5 | J9: (assumption)
A10: (a) | E10: Now we order Q0 and then Q1. Let expected Sale be E(S) | I10: . So total Q2=Q0+Q1
D11: Scenarios | G11: E[Revenue] | H11: Cost Var | I11: E[Salvage Val] | J11: E[Shipping cost] | L11: Per order cost | N11: E[Revenue]
G12: a | H12: b | I12: c | J12: d | L12: e | N12: a+c-b-d-e
D13: Dual order | E13: If E(S)≤Q0 | G13: E(S)*5 | H13: [Q0*3+Q1*3.6] | I13: [Q0-E(S)]*3*.5+Q1*3.6*.5 | J13: [Q0+Q1-E(S)]*0.5 | L13: 20*2 | N13: E(S)*5+{[Q0-E(S)]*3*.5+Q1*3.6*.5}-{[Q0*3+Q1*3.6]}-{[Q0+Q1-E(S)]*0.5}-20*2
D14: Dual order | E14: If Q0 ≤E(S)≤ Q. 1 +Q0 | G14: E(S)*5 | H14: [Q0*3+Q1*3.6] | I14: [Q0+Q1-E(S)]*3.6*.5 | J14: [Q0+Q1-E(S)]*0.5 | L14: 20*2 | N14: E(S)*5+{[Q0+Q1-E(S)]*3.6*.5}-{[Q0*3+Q1*3.6]}-{[Q0+Q1-E(S)]*0.5}-20*2
D15: Dual order | E15: if (Q1+Q0 )≤ E(S) | G15: (Q1+Q0 )*5 | H15: [Q0*3+Q1*3.6] | I15: 0 | J15: 0
D16: Single order | E16: If E(S)≤Q 0 | G16: E(S)*5 | H16: Q0*3 | I16: [Q0-E(S)]*3*.5 | J16: [Q0-E(S)]*0.5 | L16: 20 | N16: E(S)*5+{[Q0-E(S)]*3*.5}-Q0*3-{[Q0-E(S)]*0.5}-20
D17: Single order | E17: If E(S)>Q0 | G17: Q0*5 | H17: Q0*3 | I17: 0 | J17: 0 | L17: 20 | N17: Q0*(5-3)-20
A19: (b) | E19: There are two ways to manager this, eigher have just a single pre-season order or have a pre season and then in season order
E20: Lets make the payoff table. The states of nature are D⏐S=High and D⏐S=Low
E21: Decision taken are Ordering optimal quantity basis S=High or S=Low at the beginning with no top up or order S=Low optimal with a top up to match S=High
E22: At pre season cost of $3.00
E23: For D⏐S=High single order
G24: co= 3-0.5*3+.5= | H24: =3-0.5*3+0.5 -> 2
G25: cu=5-3= | H25: =5-3 -> 2
G26: P(D≤Q 0)=cu/(cu+co)= | H26: =H24/(H24+H25) -> 0.5
H27: =H26*(420-240)+240 -> 330
E29: for D⏐S=Low single order
G30: co= 3-0.5*3+.5= | H30: =3-0.5*3+0.5 -> 2
G31: cu=5-3= | H31: =5-3 -> 2
G32: P(D≤Q 0)=cu/(cu+co)= | H32: =H30/(H30+H31) -> 0.5
H33: =H32*(260-120)+120 -> 190 | I33: =190*5-200*3 -> 350
E35: for both pre and in season ordering, the pre order could be placed till Q0/low or Q0/high and then basis high signal, place the next order to add Q1
E36: This looks like a quantity discount problem except the inverse since at higher quantity, the cost is going up. So we can use a similar approach
E37: Lets find Q2/high =Q1+Q0 | H37: (Q0 can be Q0/high or Q0/low)
G38: co= 3.6-0.5*3.6+.5= | H38: =3.6-0.5*3.6+0.5 -> 2.3
G39: cu=5-3.6= | H39: =5-3.6 -> 1.4
G40: P(D≤Q0)=cu/(cu+co)= | H40: =H38/(H38+H39) -> 0.62162162
H41: =H40*(420-240)+240 -> 351.89189
E43: Lets find Q2/low =Q1+Q0
G44: co= 3.6-0.5*3.6+.5= | H44: =3.6-0.5*3.6+0.5 -> 2.3
G45: cu=5-3.6= | H45: =5-3.6 -> 1.4
G46: P(D≤Q0)=cu/(cu+co)= | H46: =H44/(H44+H45) -> 0.62162162
...

Sheet iterations 8
H2: 5 | I2: 3 | J2: 3.6 | N2: 0.45
B3: Q0 | C3: Q1 | E3: Exp sales | G3: Exp left over | H3: Revenue | I3: Var cost | J3: Var cost | K3: refund cost | L3: ord cost | M3: Profit | N3: exp profit | O3: Q0+Q1
B4: 170 | C4: 0 | E4: High | F4: =IF((240+420)/2>($B4+$C4),($B4+$C4),(240+420)/2) -> 170 | G4: =C4+B4-F4 -> 0 | H4: =F4*$H$2 -> 850 | I4: =$I$2*B4 -> 510 | J4: =$J$2*C4 -> 0 | K4: =-G4*3*0.5+0.5*G4 -> 0 | L4: =2*20 -> 40 | M4: =H4-SUM(I4:L4) -> 300 | N4: =M4*$N$2+M5*(1-$N$2) -> 300 | O4: =B4&"+"&C4 -> 170+0
B5: =B4 -> 170 | C5: =C4 -> 0 | E5: Low | F5: =IF((120+260)/2>($B5+$C5),($B5+$C5),(120+260)/2) -> 170 | G5: =C5+B5-F5 -> 0 | H5: =F5*$H$2 -> 850 | I5: =$I$2*B5 -> 510 | J5: =$J$2*C5 -> 0 | K5: =-G5*3*0.5+0.5*G5 -> 0 | L5: =2*20 -> 40 | M5: =H5-SUM(I5:L5) -> 300 | Q5: 1
B6: =B5 -> 170 | C6: =+C4+10 -> 10 | E6: High | F6: =IF((240+420)/2>($B6+$C6),($B6+$C6),(240+420)/2) -> 180 | G6: =C6+B6-F6 -> 0 | H6: =F6*$H$2 -> 900 | I6: =$I$2*B6 -> 510 | J6: =$J$2*C6 -> 36 | K6: =-G6*3*0.5+0.5*G6 -> 0 | L6: =2*20 -> 40 | M6: =H6-SUM(I6:L6) -> 314 | N6: =M6*$N$2+M7*(1-$N$2) -> 314 | O6: =B6&"+"&C6 -> 170+10 | Q6: 3
B7: =B6 -> 170 | C7: =C6 -> 10 | E7: Low | F7: =IF((120+260)/2>($B7+$C7),($B7+$C7),(120+260)/2) -> 180 | G7: =C7+B7-F7 -> 0 | H7: =F7*$H$2 -> 900 | I7: =$I$2*B7 -> 510 | J7: =$J$2*C7 -> 36 | K7: =-G7*3*0.5+0.5*G7 -> 0 | L7: =2*20 -> 40 | M7: =H7-SUM(I7:L7) -> 314 | Q7: =Q5&"+"&Q6 -> 1+3
B8: =B7 -> 170 | C8: =+C6+10 -> 20 | E8: High | F8: =IF((240+420)/2>($B8+$C8),($B8+$C8),(240+420)/2) -> 190 | G8: =C8+B8-F8 -> 0 | H8: =F8*$H$2 -> 950 | I8: =$I$2*B8 -> 510 | J8: =$J$2*C8 -> 72 | K8: =-G8*3*0.5+0.5*G8 -> 0 | L8: =2*20 -> 40 | M8: =H8-SUM(I8:L8) -> 328 | N8: =M8*$N$2+M9*(1-$N$2) -> 328 | O8: =B8&"+"&C8 -> 170+20
B9: =B8 -> 170 | C9: =C8 -> 20 | E9: Low | F9: =IF((120+260)/2>($B9+$C9),($B9+$C9),(120+260)/2) -> 190 | G9: =C9+B9-F9 -> 0 | H9: =F9*$H$2 -> 950 | I9: =$I$2*B9 -> 510 | J9: =$J$2*C9 -> 72 | K9: =-G9*3*0.5+0.5*G9 -> 0 | L9: =2*20 -> 40 | M9: =H9-SUM(I9:L9) -> 328
B10: =B9 -> 170 | C10: =+C8+10 -> 30 | E10: High | F10: =IF((240+420)/2>($B10+$C10),($B10+$C10),(240+420)/2) -> 200 | G10: =C10+B10-F10 -> 0 | H10: =F10*$H$2 -> 1000 | I10: =$I$2*B10 -> 510 | J10: =$J$2*C10 -> 108 | K10: =-G10*3*0.5+0.5*G10 -> 0 | L10: =2*20 -> 40 | M10: =H10-SUM(I10:L10) -> 342 | N10: =M10*$N$2+M11*(1-$N$2) -> 320 | O10: =B10&"+"&C10 -> 170+30
B11: =B10 -> 170 | C11: =C10 -> 30 | E11: Low | F11: =IF((120+260)/2>($B11+$C11),($B11+$C11),(120+260)/2) -> 190 | G11: =C11+B11-F11 -> 10 | H11: =F11*$H$2 -> 950 | I11: =$I$2*B11 -> 510 | J11: =$J$2*C11 -> 108 | K11: =-G11*3*0.5+0.5*G11 -> -10 | L11: =2*20 -> 40 | M11: =H11-SUM(I11:L11) -> 302
B12: =B11 -> 170 | C12: =+C10+10 -> 40 | E12: High | F12: =IF((240+420)/2>($B12+$C12),($B12+$C12),(240+420)/2) -> 210 | G12: =C12+B12-F12 -> 0 | H12: =F12*$H$2 -> 1050 | I12: =$I$2*B12 -> 510 | J12: =$J$2*C12 -> 144 | K12: =-G12*3*0.5+0.5*G12 -> 0 | L12: =2*20 -> 40 | M12: =H12-SUM(I12:L12) -> 356 | N12: =M12*$N$2+M13*(1-$N$2) -> 312 | O12: =B12&"+"&C12 -> 170+40
B13: =B12 -> 170 | C13: =C12 -> 40 | E13: Low | F13: =IF((120+260)/2>($B13+$C13),($B13+$C13),(120+260)/2) -> 190 | G13: =C13+B13-F13 -> 20 | H13: =F13*$H$2 -> 950 | I13: =$I$2*B13 -> 510 | J13: =$J$2*C13 -> 144 | K13: =-G13*3*0.5+0.5*G13 -> -20 | L13: =2*20 -> 40 | M13: =H13-SUM(I13:L13) -> 276
B14: =B13 -> 170 | C14: =+C12+10 -> 50 | E14: High | F14: =IF((240+420)/2>($B14+$C14),($B14+$C14),(240+420)/2) -> 220 | G14: =C14+B14-F14 -> 0 | H14: =F14*$H$2 -> 1100 | I14: =$I$2*B14 -> 510 | J14: =$J$2*C14 -> 180 | K14: =-G14*3*0.5+0.5*G14 -> 0 | L14: =2*20 -> 40 | M14: =H14-SUM(I14:L14) -> 370 | N14: =M14*$N$2+M15*(1-$N$2) -> 304 | O14: =B14&"+"&C14 -> 170+50
B15: =B14 -> 170 | C15: =C14 -> 50 | E15: Low | F15: =IF((120+260)/2>($B15+$C15),($B15+$C15),(120+260)/2) -> 190 | G15: =C15+B15-F15 -> 30 | H15: =F15*$H$2 -> 950 | I15: =$I$2*B15 -> 510 | J15: =$J$2*C15 -> 180 | K15: =-G15*3*0.5+0.5*G15 -> -30 | L15: =2*20 -> 40 | M15: =H15-SUM(I15:L15) -> 250
B16: =B15 -> 170 | C16: =+C14+10 -> 60 | E16: High | F16: =IF((240+420)/2>($B16+$C16),($B16+$C16),(240+420)/2) -> 230 | G16: =C16+B16-F16 -> 0 | H16: =F16*$H$2 -> 1150 | I16: =$I$2*B16 -> 510 | J16: =$J$2*C16 -> 216 | K16: =-G16*3*0.5+0.5*G16 -> 0 | L16: =2*20 -> 40 | M16: =H16-SUM(I16:L16) -> 384 | N16: =M16*$N$2+M17*(1-$N$2) -> 296 | O16: =B16&"+"&C16 -> 170+60
B17: =B16 -> 170 | C17: =C16 -> 60 | E17: Low | F17: =IF((120+260)/2>($B17+$C17),($B17+$C17),(120+260)/2) -> 190 | G17: =C17+B17-F17 -> 40 | H17: =F17*$H$2 -> 950 | I17: =$I$2*B17 -> 510 | J17: =$J$2*C17 -> 216 | K17: =-G17*3*0.5+0.5*G17 -> -40 | L17: =2*20 -> 40 | M17: =H17-SUM(I17:L17) -> 224
B18: =B17 -> 170 | C18: =+C16+10 -> 70 | E18: High | F18: =IF((240+420)/2>($B18+$C18),($B18+$C18),(240+420)/2) -> 240 | G18: =C18+B18-F18 -> 0 | H18: =F18*$H$2 -> 1200 | I18: =$I$2*B18 -> 510 | J18: =$J$2*C18 -> 252 | K18: =-G18*3*0.5+0.5*G18 -> 0 | L18: =2*20 -> 40 | M18: =H18-SUM(I18:L18) -> 398 | N18: =M18*$N$2+M19*(1-$N$2) -> 288 | O18: =B18&"+"&C18 -> 170+70
B19: =B18 -> 170 | C19: =C18 -> 70 | E19: Low | F19: =IF((120+260)/2>($B19+$C19),($B19+$C19),(120+260)/2) -> 190 | G19: =C19+B19-F19 -> 50 | H19: =F19*$H$2 -> 950 | I19: =$I$2*B19 -> 510 | J19: =$J$2*C19 -> 252 | K19: =-G19*3*0.5+0.5*G19 -> -50 | L19: =2*20 -> 40 | M19: =H19-SUM(I19:L19) -> 198
B20: =B19 -> 170 | C20: =+C18+10 -> 80 | E20: High | F20: =IF((240+420)/2>($B20+$C20),($B20+$C20),(240+420)/2) -> 250 | G20: =C20+B20-F20 -> 0 | H20: =F20*$H$2 -> 1250 | I20: =$I$2*B20 -> 510 | J20: =$J$2*C20 -> 288 | K20: =-G20*3*0.5+0.5*G20 -> 0 | L20: =2*20 -> 40 | M20: =H20-SUM(I20:L20) -> 412 | N20: =M20*$N$2+M21*(1-$N$2) -> 280 | O20: =B20&"+"&C20 -> 170+80
B21: =B20 -> 170 | C21: =C20 -> 80 | E21: Low | F21: =IF((120+260)/2>($B21+$C21),($B21+$C21),(120+260)/2) -> 190 | G21: =C21+B21-F21 -> 60 | H21: =F21*$H$2 -> 950 | I21: =$I$2*B21 -> 510 | J21: =$J$2*C21 -> 288 | K21: =-G21*3*0.5+0.5*G21 -> -60 | L21: =2*20 -> 40 | M21: =H21-SUM(I21:L21) -> 172
B22: =B21 -> 170 | C22: =+C20+10 -> 90 | E22: High | F22: =IF((240+420)/2>($B22+$C22),($B22+$C22),(240+420)/2) -> 260 | G22: =C22+B22-F22 -> 0 | H22: =F22*$H$2 -> 1300 | I22: =$I$2*B22 -> 510 | J22: =$J$2*C22 -> 324 | K22: =-G22*3*0.5+0.5*G22 -> 0 | L22: =2*20 -> 40 | M22: =H22-SUM(I22:L22) -> 426 | N22: =M22*$N$2+M23*(1-$N$2) -> 272 | O22: =B22&"+"&C22 -> 170+90
B23: =B22 -> 170 | C23: =C22 -> 90 | E23: Low | F23: =IF((120+260)/2>($B23+$C23),($B23+$C23),(120+260)/2) -> 190 | G23: =C23+B23-F23 -> 70 | H23: =F23*$H$2 -> 950 | I23: =$I$2*B23 -> 510 | J23: =$J$2*C23 -> 324 | K23: =-G23*3*0.5+0.5*G23 -> -70 | L23: =2*20 -> 40 | M23: =H23-SUM(I23:L23) -> 146
B24: =B23 -> 170 | C24: =+C22+10 -> 100 | E24: High | F24: =IF((240+420)/2>($B24+$C24),($B24+$C24),(240+420)/2) -> 270 | G24: =C24+B24-F24 -> 0 | H24: =F24*$H$2 -> 1350 | I24: =$I$2*B24 -> 510 | J24: =$J$2*C24 -> 360 | K24: =-G24*3*0.5+0.5*G24 -> 0 | L24: =2*20 -> 40 | M24: =H24-SUM(I24:L24) -> 440 | N24: =M24*$N$2+M25*(1-$N$2) -> 264 | O24: =B24&"+"&C24 -> 170+100
B25: =B24 -> 170 | C25: =C24 -> 100 | E25: Low | F25: =IF((120+260)/2>($B25+$C25),($B25+$C25),(120+260)/2) -> 190 | G25: =C25+B25-F25 -> 80 | H25: =F25*$H$2 -> 950 | I25: =$I$2*B25 -> 510 | J25: =$J$2*C25 -> 360 | K25: =-G25*3*0.5+0.5*G25 -> -80 | L25: =2*20 -> 40 | M25: =H25-SUM(I25:L25) -> 120
B26: =B25 -> 170 | C26: =+C24+10 -> 110 | E26: High | F26: =IF((240+420)/2>($B26+$C26),($B26+$C26),(240+420)/2) -> 280 | G26: =C26+B26-F26 -> 0 | H26: =F26*$H$2 -> 1400 | I26: =$I$2*B26 -> 510 | J26: =$J$2*C26 -> 396 | K26: =-G26*3*0.5+0.5*G26 -> 0 | L26: =2*20 -> 40 | M26: =H26-SUM(I26:L26) -> 454 | N26: =M26*$N$2+M27*(1-$N$2) -> 256 | O26: =B26&"+"&C26 -> 170+110
B27: =B26 -> 170 | C27: =C26 -> 110 | E27: Low | F27: =IF((120+260)/2>($B27+$C27),($B27+$C27),(120+260)/2) -> 190 | G27: =C27+B27-F27 -> 90 | H27: =F27*$H$2 -> 950 | I27: =$I$2*B27 -> 510 | J27: =$J$2*C27 -> 396 | K27: =-G27*3*0.5+0.5*G27 -> -90 | L27: =2*20 -> 40 | M27: =H27-SUM(I27:L27) -> 94
B28: =B27 -> 170 | C28: =+C26+10 -> 120 | E28: High | F28: =IF((240+420)/2>($B28+$C28),($B28+$C28),(240+420)/2) -> 290 | G28: =C28+B28-F28 -> 0 | H28: =F28*$H$2 -> 1450 | I28: =$I$2*B28 -> 510 | J28: =$J$2*C28 -> 432 | K28: =-G28*3*0.5+0.5*G28 -> 0 | L28: =2*20 -> 40 | M28: =H28-SUM(I28:L28) -> 468 | N28: =M28*$N$2+M29*(1-$N$2) -> 248 | O28: =B28&"+"&C28 -> 170+120
B29: =B28 -> 170 | C29: =C28 -> 120 | E29: Low | F29: =IF((120+260)/2>($B29+$C29),($B29+$C29),(120+260)/2) -> 190 | G29: =C29+B29-F29 -> 100 | H29: =F29*$H$2 -> 950 | I29: =$I$2*B29 -> 510 | J29: =$J$2*C29 -> 432 | K29: =-G29*3*0.5+0.5*G29 -> -100 | L29: =2*20 -> 40 | M29: =H29-SUM(I29:L29) -> 68
B30: =B29 -> 170 | C30: =+C28+10 -> 130 | E30: High | F30: =IF((240+420)/2>($B30+$C30),($B30+$C30),(240+420)/2) -> 300 | G30: =C30+B30-F30 -> 0 | H30: =F30*$H$2 -> 1500 | I30: =$I$2*B30 -> 510 | J30: =$J$2*C30 -> 468 | K30: =-G30*3*0.5+0.5*G30 -> 0 | L30: =2*20 -> 40 | M30: =H30-SUM(I30:L30) -> 482 | N30: =M30*$N$2+M31*(1-$N$2) -> 240 | O30: =B30&"+"&C30 -> 170+130
B31: =B30 -> 170 | C31: =C30 -> 130 | E31: Low | F31: =IF((120+260)/2>($B31+$C31),($B31+$C31),(120+260)/2) -> 190 | G31: =C31+B31-F31 -> 110 | H31: =F31*$H$2 -> 950 | I31: =$I$2*B31 -> 510 | J31: =$J$2*C31 -> 468 | K31: =-G31*3*0.5+0.5*G31 -> -110 | L31: =2*20 -> 40 | M31: =H31-SUM(I31:L31) -> 42
B32: =B31 -> 170 | C32: =+C30+10 -> 140 | E32: High | F32: =IF((240+420)/2>($B32+$C32),($B32+$C32),(240+420)/2) -> 310 | G32: =C32+B32-F32 -> 0 | H32: =F32*$H$2 -> 1550 | I32: =$I$2*B32 -> 510 | J32: =$J$2*C32 -> 504 | K32: =-G32*3*0.5+0.5*G32 -> 0 | L32: =2*20 -> 40 | M32: =H32-SUM(I32:L32) -> 496 | N32: =M32*$N$2+M33*(1-$N$2) -> 232 | O32: =B32&"+"&C32 -> 170+140
B33: =B32 -> 170 | C33: =C32 -> 140 | E33: Low | F33: =IF((120+260)/2>($B33+$C33),($B33+$C33),(120+260)/2) -> 190 | G33: =C33+B33-F33 -> 120 | H33: =F33*$H$2 -> 950 | I33: =$I$2*B33 -> 510 | J33: =$J$2*C33 -> 504 | K33: =-G33*3*0.5+0.5*G33 -> -120 | L33: =2*20 -> 40 | M33: =H33-SUM(I33:L33) -> 16
B34: =B33 -> 170 | C34: =+C32+10 -> 150 | E34: High | F34: =IF((240+420)/2>($B34+$C34),($B34+$C34),(240+420)/2) -> 320 | G34: =C34+B34-F34 -> 0 | H34: =F34*$H$2 -> 1600 | I34: =$I$2*B34 -> 510 | J34: =$J$2*C34 -> 540 | K34: =-G34*3*0.5+0.5*G34 -> 0 | L34: =2*20 -> 40 | M34: =H34-SUM(I34:L34) -> 510 | N34: =M34*$N$2+M35*(1-$N$2) -> 224 | O34: =B34&"+"&C34 -> 170+150
B35: =B34 -> 170 | C35: =C34 -> 150 | E35: Low | F35: =IF((120+260)/2>($B35+$C35),($B35+$C35),(120+260)/2) -> 190 | G35: =C35+B35-F35 -> 130 | H35: =F35*$H$2 -> 950 | I35: =$I$2*B35 -> 510 | J35: =$J$2*C35 -> 540 | K35: =-G35*3*0.5+0.5*G35 -> -130 | L35: =2*20 -> 40 | M35: =H35-SUM(I35:L35) -> -10
B36: =B35 -> 170 | C36: =+C34+10 -> 160 | E36: High | F36: =IF((240+420)/2>($B36+$C36),($B36+$C36),(240+420)/2) -> 330 | G36: =C36+B36-F36 -> 0 | H36: =F36*$H$2 -> 1650 | I36: =$I$2*B36 -> 510 | J36: =$J$2*C36 -> 576 | K36: =-G36*3*0.5+0.5*G36 -> 0 | L36: =2*20 -> 40 | M36: =H36-SUM(I36:L36) -> 524 | N36: =M36*$N$2+M37*(1-$N$2) -> 216 | O36: =B36&"+"&C36 -> 170+160
B37: =B36 -> 170 | C37: =C36 -> 160 | E37: Low | F37: =IF((120+260)/2>($B37+$C37),($B37+$C37),(120+260)/2) -> 190 | G37: =C37+B37-F37 -> 140 | H37: =F37*$H$2 -> 950 | I37: =$I$2*B37 -> 510 | J37: =$J$2*C37 -> 576 | K37: =-G37*3*0.5+0.5*G37 -> -140 | L37: =2*20 -> 40 | M37: =H37-SUM(I37:L37) -> -36
B38: =B37 -> 170 | C38: =+C36+10 -> 170 | E38: High | F38: =IF((240+420)/2>($B38+$C38),($B38+$C38),(240+420)/2) -> 330 | G38: =C38+B38-F38 -> 10 | H38: =F38*$H$2 -> 1650 | I38: =$I$2*B38 -> 510 | J38: =$J$2*C38 -> 612 | K38: =-G38*3*0.5+0.5*G38 -> -10 | L38: =2*20 -> 40 | M38: =H38-SUM(I38:L38) -> 498 | N38: =M38*$N$2+M39*(1-$N$2) -> 190 | O38: =B38&"+"&C38 -> 170+170
B39: =B38 -> 170 | C39: =C38 -> 170 | E39: Low | F39: =IF((120+260)/2>($B39+$C39),($B39+$C39),(120+260)/2) -> 190 | G39: =C39+B39-F39 -> 150 | H39: =F39*$H$2 -> 950 | I39: =$I$2*B39 -> 510 | J39: =$J$2*C39 -> 612 | K39: =-G39*3*0.5+0.5*G39 -> -150 | L39: =2*20 -> 40 | M39: =H39-SUM(I39:L39) -> -62
B40: =B39 -> 170 | C40: =+C38+10 -> 180 | E40: High | F40: =IF((240+420)/2>($B40+$C40),($B40+$C40),(240+420)/2) -> 330 | G40: =C40+B40-F40 -> 20 | H40: =F40*$H$2 -> 1650 | I40: =$I$2*B40 -> 510 | J40: =$J$2*C40 -> 648 | K40: =-G40*3*0.5+0.5*G40 -> -20 | L40: =2*20 -> 40 | M40: =H40-SUM(I40:L40) -> 472 | N40: =M40*$N$2+M41*(1-$N$2) -> 164 | O40: =B40&"+"&C40 -> 170+180
B41: =B40 -> 170 | C41: =C40 -> 180 | E41: Low | F41: =IF((120+260)/2>($B41+$C41),($B41+$C41),(120+260)/2) -> 190 | G41: =C41+B41-F41 -> 160 | H41: =F41*$H$2 -> 950 | I41: =$I$2*B41 -> 510 | J41: =$J$2*C41 -> 648 | K41: =-G41*3*0.5+0.5*G41 -> -160 | L41: =2*20 -> 40 | M41: =H41-SUM(I41:L41) -> -88
...

Sheet iterations 8 (SH)
M1: Assumption
H2: 5 | I2: 3 | J2: 3.6 | M2: P(D=H⏐S=H) | N2: 0.8
B3: Q0 | C3: Q1 | E3: Exp sales | G3: Exp left over | H3: Revenue | I3: Var cost | J3: Var cost | K3: refund cost | L3: ord cost | M3: Profit | N3: exp profit | O3: Q0+Q1
A4: 1 | B4: 330 | C4: 0 | E4: High | F4: =IF((240+420)/2>($B4+$C4),($B4+$C4),(240+420)/2) -> 330 | G4: =C4+B4-F4 -> 0 | H4: =F4*$H$2 -> 1650 | I4: =$I$2*B4 -> 990 | J4: =$J$2*C4 -> 0 | K4: =-G4*3*0.5+0.5*G4 -> 0 | L4: =2*20 -> 40 | M4: =H4-SUM(I4:L4) -> 620 | N4: =M4*$N$2+M5*(1-$N$2) -> 508 | O4: =B4&"+"&C4 -> 330+0 | P4: =N4*N2 -> 406.4
B5: =B4 -> 330 | C5: =C4 -> 0 | E5: Low | F5: =IF((120+260)/2>($B5+$C5),($B5+$C5),(120+260)/2) -> 190 | G5: =C5+B5-F5 -> 140 | H5: =F5*$H$2 -> 950 | I5: =$I$2*B5 -> 990 | J5: =$J$2*C5 -> 0 | K5: =-G5*3*0.5+0.5*G5 -> -140 | L5: =2*20 -> 40 | M5: =H5-SUM(I5:L5) -> 60 | Q5: 170
A6: =A4+2 -> 3 | B6: =B5 -> 330 | C6: =+C4+10 -> 10 | E6: High | F6: =IF((240+420)/2>($B6+$C6),($B6+$C6),(240+420)/2) -> 330 | G6: =C6+B6-F6 -> 10 | H6: =F6*$H$2 -> 1650 | I6: =$I$2*B6 -> 990 | J6: =$J$2*C6 -> 36 | K6: =-G6*3*0.5+0.5*G6 -> -10 | L6: =2*20 -> 40 | M6: =H6-SUM(I6:L6) -> 594 | N6: =M6*$N$2+M7*(1-$N$2) -> 482 | O6: =B6&"+"&C6 -> 330+10 | Q6: =Q5+10 -> 180
B7: =B6 -> 330 | C7: =C6 -> 10 | E7: Low | F7: =IF((120+260)/2>($B7+$C7),($B7+$C7),(120+260)/2) -> 190 | G7: =C7+B7-F7 -> 150 | H7: =F7*$H$2 -> 950 | I7: =$I$2*B7 -> 990 | J7: =$J$2*C7 -> 36 | K7: =-G7*3*0.5+0.5*G7 -> -150 | L7: =2*20 -> 40 | M7: =H7-SUM(I7:L7) -> 34 | Q7: =Q6+10 -> 190
A8: =A6+2 -> 5 | B8: =B7 -> 330 | C8: =+C6+10 -> 20 | E8: High | F8: =IF((240+420)/2>($B8+$C8),($B8+$C8),(240+420)/2) -> 330 | G8: =C8+B8-F8 -> 20 | H8: =F8*$H$2 -> 1650 | I8: =$I$2*B8 -> 990 | J8: =$J$2*C8 -> 72 | K8: =-G8*3*0.5+0.5*G8 -> -20 | L8: =2*20 -> 40 | M8: =H8-SUM(I8:L8) -> 568 | N8: =M8*$N$2+M9*(1-$N$2) -> 456 | O8: =B8&"+"&C8 -> 330+20 | Q8: =Q7+10 -> 200
B9: =B8 -> 330 | C9: =C8 -> 20 | E9: Low | F9: =IF((120+260)/2>($B9+$C9),($B9+$C9),(120+260)/2) -> 190 | G9: =C9+B9-F9 -> 160 | H9: =F9*$H$2 -> 950 | I9: =$I$2*B9 -> 990 | J9: =$J$2*C9 -> 72 | K9: =-G9*3*0.5+0.5*G9 -> -160 | L9: =2*20 -> 40 | M9: =H9-SUM(I9:L9) -> 8 | Q9: =Q8+10 -> 210
A10: =A8+2 -> 7 | B10: =B9 -> 330 | C10: =+C8+10 -> 30 | E10: High | F10: =IF((240+420)/2>($B10+$C10),($B10+$C10),(240+420)/2) -> 330 | G10: =C10+B10-F10 -> 30 | H10: =F10*$H$2 -> 1650 | I10: =$I$2*B10 -> 990 | J10: =$J$2*C10 -> 108 | K10: =-G10*3*0.5+0.5*G10 -> -30 | L10: =2*20 -> 40 | M10: =H10-SUM(I10:L10) -> 542 | N10: =M10*$N$2+M11*(1-$N$2) -> 430 | O10: =B10&"+"&C10 -> 330+30 | Q10: =Q9+10 -> 220
B11: =B10 -> 330 | C11: =C10 -> 30 | E11: Low | F11: =IF((120+260)/2>($B11+$C11),($B11+$C11),(120+260)/2) -> 190 | G11: =C11+B11-F11 -> 170 | H11: =F11*$H$2 -> 950 | I11: =$I$2*B11 -> 990 | J11: =$J$2*C11 -> 108 | K11: =-G11*3*0.5+0.5*G11 -> -170 | L11: =2*20 -> 40 | M11: =H11-SUM(I11:L11) -> -18 | Q11: =Q10+10 -> 230
A12: =A10+2 -> 9 | B12: =B11 -> 330 | C12: =+C10+10 -> 40 | E12: High | F12: =IF((240+420)/2>($B12+$C12),($B12+$C12),(240+420)/2) -> 330 | G12: =C12+B12-F12 -> 40 | H12: =F12*$H$2 -> 1650 | I12: =$I$2*B12 -> 990 | J12: =$J$2*C12 -> 144 | K12: =-G12*3*0.5+0.5*G12 -> -40 | L12: =2*20 -> 40 | M12: =H12-SUM(I12:L12) -> 516 | N12: =M12*$N$2+M13*(1-$N$2) -> 404 | O12: =B12&"+"&C12 -> 330+40 | Q12: =Q11+10 -> 240
B13: =B12 -> 330 | C13: =C12 -> 40 | E13: Low | F13: =IF((120+260)/2>($B13+$C13),($B13+$C13),(120+260)/2) -> 190 | G13: =C13+B13-F13 -> 180 | H13: =F13*$H$2 -> 950 | I13: =$I$2*B13 -> 990 | J13: =$J$2*C13 -> 144 | K13: =-G13*3*0.5+0.5*G13 -> -180 | L13: =2*20 -> 40 | M13: =H13-SUM(I13:L13) -> -44 | Q13: =Q12+10 -> 250
A14: =A12+2 -> 11 | B14: =B13 -> 330 | C14: =+C12+10 -> 50 | E14: High | F14: =IF((240+420)/2>($B14+$C14),($B14+$C14),(240+420)/2) -> 330 | G14: =C14+B14-F14 -> 50 | H14: =F14*$H$2 -> 1650 | I14: =$I$2*B14 -> 990 | J14: =$J$2*C14 -> 180 | K14: =-G14*3*0.5+0.5*G14 -> -50 | L14: =2*20 -> 40 | M14: =H14-SUM(I14:L14) -> 490 | N14: =M14*$N$2+M15*(1-$N$2) -> 378 | O14: =B14&"+"&C14 -> 330+50 | Q14: =Q13+10 -> 260
B15: =B14 -> 330 | C15: =C14 -> 50 | E15: Low | F15: =IF((120+260)/2>($B15+$C15),($B15+$C15),(120+260)/2) -> 190 | G15: =C15+B15-F15 -> 190 | H15: =F15*$H$2 -> 950 | I15: =$I$2*B15 -> 990 | J15: =$J$2*C15 -> 180 | K15: =-G15*3*0.5+0.5*G15 -> -190 | L15: =2*20 -> 40 | M15: =H15-SUM(I15:L15) -> -70 | Q15: =Q14+10 -> 270
A16: =A14+2 -> 13 | B16: =B15 -> 330 | C16: =+C14+10 -> 60 | E16: High | F16: =IF((240+420)/2>($B16+$C16),($B16+$C16),(240+420)/2) -> 330 | G16: =C16+B16-F16 -> 60 | H16: =F16*$H$2 -> 1650 | I16: =$I$2*B16 -> 990 | J16: =$J$2*C16 -> 216 | K16: =-G16*3*0.5+0.5*G16 -> -60 | L16: =2*20 -> 40 | M16: =H16-SUM(I16:L16) -> 464 | N16: =M16*$N$2+M17*(1-$N$2) -> 352 | O16: =B16&"+"&C16 -> 330+60 | Q16: =Q15+10 -> 280
B17: =B16 -> 330 | C17: =C16 -> 60 | E17: Low | F17: =IF((120+260)/2>($B17+$C17),($B17+$C17),(120+260)/2) -> 190 | G17: =C17+B17-F17 -> 200 | H17: =F17*$H$2 -> 950 | I17: =$I$2*B17 -> 990 | J17: =$J$2*C17 -> 216 | K17: =-G17*3*0.5+0.5*G17 -> -200 | L17: =2*20 -> 40 | M17: =H17-SUM(I17:L17) -> -96 | Q17: =Q16+10 -> 290
A18: =A16+2 -> 15 | B18: =B17 -> 330 | C18: =+C16+10 -> 70 | E18: High | F18: =IF((240+420)/2>($B18+$C18),($B18+$C18),(240+420)/2) -> 330 | G18: =C18+B18-F18 -> 70 | H18: =F18*$H$2 -> 1650 | I18: =$I$2*B18 -> 990 | J18: =$J$2*C18 -> 252 | K18: =-G18*3*0.5+0.5*G18 -> -70 | L18: =2*20 -> 40 | M18: =H18-SUM(I18:L18) -> 438 | N18: =M18*$N$2+M19*(1-$N$2) -> 326 | O18: =B18&"+"&C18 -> 330+70 | Q18: =Q17+10 -> 300
B19: =B18 -> 330 | C19: =C18 -> 70 | E19: Low | F19: =IF((120+260)/2>($B19+$C19),($B19+$C19),(120+260)/2) -> 190 | G19: =C19+B19-F19 -> 210 | H19: =F19*$H$2 -> 950 | I19: =$I$2*B19 -> 990 | J19: =$J$2*C19 -> 252 | K19: =-G19*3*0.5+0.5*G19 -> -210 | L19: =2*20 -> 40 | M19: =H19-SUM(I19:L19) -> -122 | Q19: =Q18+10 -> 310
A20: =A18+2 -> 17 | B20: =B19 -> 330 | C20: =+C18+10 -> 80 | E20: High | F20: =IF((240+420)/2>($B20+$C20),($B20+$C20),(240+420)/2) -> 330 | G20: =C20+B20-F20 -> 80 | H20: =F20*$H$2 -> 1650 | I20: =$I$2*B20 -> 990 | J20: =$J$2*C20 -> 288 | K20: =-G20*3*0.5+0.5*G20 -> -80 | L20: =2*20 -> 40 | M20: =H20-SUM(I20:L20) -> 412 | N20: =M20*$N$2+M21*(1-$N$2) -> 300 | O20: =B20&"+"&C20 -> 330+80 | Q20: =Q19+10 -> 320
B21: =B20 -> 330 | C21: =C20 -> 80 | E21: Low | F21: =IF((120+260)/2>($B21+$C21),($B21+$C21),(120+260)/2) -> 190 | G21: =C21+B21-F21 -> 220 | H21: =F21*$H$2 -> 950 | I21: =$I$2*B21 -> 990 | J21: =$J$2*C21 -> 288 | K21: =-G21*3*0.5+0.5*G21 -> -220 | L21: =2*20 -> 40 | M21: =H21-SUM(I21:L21) -> -148 | Q21: =Q20+10 -> 330
A22: =A20+2 -> 19 | B22: =B21 -> 330 | C22: =+C20+10 -> 90 | E22: High | F22: =IF((240+420)/2>($B22+$C22),($B22+$C22),(240+420)/2) -> 330 | G22: =C22+B22-F22 -> 90 | H22: =F22*$H$2 -> 1650 | I22: =$I$2*B22 -> 990 | J22: =$J$2*C22 -> 324 | K22: =-G22*3*0.5+0.5*G22 -> -90 | L22: =2*20 -> 40 | M22: =H22-SUM(I22:L22) -> 386 | N22: =M22*$N$2+M23*(1-$N$2) -> 274 | O22: =B22&"+"&C22 -> 330+90 | Q22: =Q21+10 -> 340
B23: =B22 -> 330 | C23: =C22 -> 90 | E23: Low | F23: =IF((120+260)/2>($B23+$C23),($B23+$C23),(120+260)/2) -> 190 | G23: =C23+B23-F23 -> 230 | H23: =F23*$H$2 -> 950 | I23: =$I$2*B23 -> 990 | J23: =$J$2*C23 -> 324 | K23: =-G23*3*0.5+0.5*G23 -> -230 | L23: =2*20 -> 40 | M23: =H23-SUM(I23:L23) -> -174 | Q23: =Q22+10 -> 350
A24: =A22+2 -> 21 | B24: =B23 -> 330 | C24: =+C22+10 -> 100 | E24: High | F24: =IF((240+420)/2>($B24+$C24),($B24+$C24),(240+420)/2) -> 330 | G24: =C24+B24-F24 -> 100 | H24: =F24*$H$2 -> 1650 | I24: =$I$2*B24 -> 990 | J24: =$J$2*C24 -> 360 | K24: =-G24*3*0.5+0.5*G24 -> -100 | L24: =2*20 -> 40 | M24: =H24-SUM(I24:L24) -> 360 | N24: =M24*$N$2+M25*(1-$N$2) -> 248 | O24: =B24&"+"&C24 -> 330+100 | Q24: =Q23+10 -> 360
B25: =B24 -> 330 | C25: =C24 -> 100 | E25: Low | F25: =IF((120+260)/2>($B25+$C25),($B25+$C25),(120+260)/2) -> 190 | G25: =C25+B25-F25 -> 240 | H25: =F25*$H$2 -> 950 | I25: =$I$2*B25 -> 990 | J25: =$J$2*C25 -> 360 | K25: =-G25*3*0.5+0.5*G25 -> -240 | L25: =2*20 -> 40 | M25: =H25-SUM(I25:L25) -> -200 | Q25: =Q24+10 -> 370
A26: =A24+2 -> 23 | B26: =B25 -> 330 | C26: =+C24+10 -> 110 | E26: High | F26: =IF((240+420)/2>($B26+$C26),($B26+$C26),(240+420)/2) -> 330 | G26: =C26+B26-F26 -> 110 | H26: =F26*$H$2 -> 1650 | I26: =$I$2*B26 -> 990 | J26: =$J$2*C26 -> 396 | K26: =-G26*3*0.5+0.5*G26 -> -110 | L26: =2*20 -> 40 | M26: =H26-SUM(I26:L26) -> 334 | N26: =M26*$N$2+M27*(1-$N$2) -> 222 | O26: =B26&"+"&C26 -> 330+110 | Q26: =Q25+10 -> 380
B27: =B26 -> 330 | C27: =C26 -> 110 | E27: Low | F27: =IF((120+260)/2>($B27+$C27),($B27+$C27),(120+260)/2) -> 190 | G27: =C27+B27-F27 -> 250 | H27: =F27*$H$2 -> 950 | I27: =$I$2*B27 -> 990 | J27: =$J$2*C27 -> 396 | K27: =-G27*3*0.5+0.5*G27 -> -250 | L27: =2*20 -> 40 | M27: =H27-SUM(I27:L27) -> -226 | Q27: =Q26+10 -> 390
A28: =A26+2 -> 25 | B28: =B27 -> 330 | C28: =+C26+10 -> 120 | E28: High | F28: =IF((240+420)/2>($B28+$C28),($B28+$C28),(240+420)/2) -> 330 | G28: =C28+B28-F28 -> 120 | H28: =F28*$H$2 -> 1650 | I28: =$I$2*B28 -> 990 | J28: =$J$2*C28 -> 432 | K28: =-G28*3*0.5+0.5*G28 -> -120 | L28: =2*20 -> 40 | M28: =H28-SUM(I28:L28) -> 308 | N28: =M28*$N$2+M29*(1-$N$2) -> 196 | O28: =B28&"+"&C28 -> 330+120 | Q28: =Q27+10 -> 400
B29: =B28 -> 330 | C29: =C28 -> 120 | E29: Low | F29: =IF((120+260)/2>($B29+$C29),($B29+$C29),(120+260)/2) -> 190 | G29: =C29+B29-F29 -> 260 | H29: =F29*$H$2 -> 950 | I29: =$I$2*B29 -> 990 | J29: =$J$2*C29 -> 432 | K29: =-G29*3*0.5+0.5*G29 -> -260 | L29: =2*20 -> 40 | M29: =H29-SUM(I29:L29) -> -252 | Q29: =Q28+10 -> 410
A30: =A28+2 -> 27 | B30: =B29 -> 330 | C30: =+C28+10 -> 130 | E30: High | F30: =IF((240+420)/2>($B30+$C30),($B30+$C30),(240+420)/2) -> 330 | G30: =C30+B30-F30 -> 130 | H30: =F30*$H$2 -> 1650 | I30: =$I$2*B30 -> 990 | J30: =$J$2*C30 -> 468 | K30: =-G30*3*0.5+0.5*G30 -> -130 | L30: =2*20 -> 40 | M30: =H30-SUM(I30:L30) -> 282 | N30: =M30*$N$2+M31*(1-$N$2) -> 170 | O30: =B30&"+"&C30 -> 330+130 | Q30: =Q29+10 -> 420
B31: =B30 -> 330 | C31: =C30 -> 130 | E31: Low | F31: =IF((120+260)/2>($B31+$C31),($B31+$C31),(120+260)/2) -> 190 | G31: =C31+B31-F31 -> 270 | H31: =F31*$H$2 -> 950 | I31: =$I$2*B31 -> 990 | J31: =$J$2*C31 -> 468 | K31: =-G31*3*0.5+0.5*G31 -> -270 | L31: =2*20 -> 40 | M31: =H31-SUM(I31:L31) -> -278
A32: =A30+2 -> 29 | B32: =B31 -> 330 | C32: =+C30+10 -> 140 | E32: High | F32: =IF((240+420)/2>($B32+$C32),($B32+$C32),(240+420)/2) -> 330 | G32: =C32+B32-F32 -> 140 | H32: =F32*$H$2 -> 1650 | I32: =$I$2*B32 -> 990 | J32: =$J$2*C32 -> 504 | K32: =-G32*3*0.5+0.5*G32 -> -140 | L32: =2*20 -> 40 | M32: =H32-SUM(I32:L32) -> 256 | N32: =M32*$N$2+M33*(1-$N$2) -> 144 | O32: =B32&"+"&C32 -> 330+140
B33: =B32 -> 330 | C33: =C32 -> 140 | E33: Low | F33: =IF((120+260)/2>($B33+$C33),($B33+$C33),(120+260)/2) -> 190 | G33: =C33+B33-F33 -> 280 | H33: =F33*$H$2 -> 950 | I33: =$I$2*B33 -> 990 | J33: =$J$2*C33 -> 504 | K33: =-G33*3*0.5+0.5*G33 -> -280 | L33: =2*20 -> 40 | M33: =H33-SUM(I33:L33) -> -304
A34: =A32+2 -> 31 | B34: =B33 -> 330 | C34: =+C32+10 -> 150 | E34: High | F34: =IF((240+420)/2>($B34+$C34),($B34+$C34),(240+420)/2) -> 330 | G34: =C34+B34-F34 -> 150 | H34: =F34*$H$2 -> 1650 | I34: =$I$2*B34 -> 990 | J34: =$J$2*C34 -> 540 | K34: =-G34*3*0.5+0.5*G34 -> -150 | L34: =2*20 -> 40 | M34: =H34-SUM(I34:L34) -> 230 | N34: =M34*$N$2+M35*(1-$N$2) -> 118 | O34: =B34&"+"&C34 -> 330+150
B35: =B34 -> 330 | C35: =C34 -> 150 | E35: Low | F35: =IF((120+260)/2>($B35+$C35),($B35+$C35),(120+260)/2) -> 190 | G35: =C35+B35-F35 -> 290 | H35: =F35*$H$2 -> 950 | I35: =$I$2*B35 -> 990 | J35: =$J$2*C35 -> 540 | K35: =-G35*3*0.5+0.5*G35 -> -290 | L35: =2*20 -> 40 | M35: =H35-SUM(I35:L35) -> -330
A36: =A34+2 -> 33 | B36: =B35 -> 330 | C36: =+C34+10 -> 160 | E36: High | F36: =IF((240+420)/2>($B36+$C36),($B36+$C36),(240+420)/2) -> 330 | G36: =C36+B36-F36 -> 160 | H36: =F36*$H$2 -> 1650 | I36: =$I$2*B36 -> 990 | J36: =$J$2*C36 -> 576 | K36: =-G36*3*0.5+0.5*G36 -> -160 | L36: =2*20 -> 40 | M36: =H36-SUM(I36:L36) -> 204 | N36: =M36*$N$2+M37*(1-$N$2) -> 92 | O36: =B36&"+"&C36 -> 330+160
B37: =B36 -> 330 | C37: =C36 -> 160 | E37: Low | F37: =IF((120+260)/2>($B37+$C37),($B37+$C37),(120+260)/2) -> 190 | G37: =C37+B37-F37 -> 300 | H37: =F37*$H$2 -> 950 | I37: =$I$2*B37 -> 990 | J37: =$J$2*C37 -> 576 | K37: =-G37*3*0.5+0.5*G37 -> -300 | L37: =2*20 -> 40 | M37: =H37-SUM(I37:L37) -> -356
A38: =A36+2 -> 35 | B38: =B37 -> 330 | C38: =+C36+10 -> 170 | E38: High | F38: =IF((240+420)/2>($B38+$C38),($B38+$C38),(240+420)/2) -> 330 | G38: =C38+B38-F38 -> 170 | H38: =F38*$H$2 -> 1650 | I38: =$I$2*B38 -> 990 | J38: =$J$2*C38 -> 612 | K38: =-G38*3*0.5+0.5*G38 -> -170 | L38: =2*20 -> 40 | M38: =H38-SUM(I38:L38) -> 178 | N38: =M38*$N$2+M39*(1-$N$2) -> 66 | O38: =B38&"+"&C38 -> 330+170
B39: =B38 -> 330 | C39: =C38 -> 170 | E39: Low | F39: =IF((120+260)/2>($B39+$C39),($B39+$C39),(120+260)/2) -> 190 | G39: =C39+B39-F39 -> 310 | H39: =F39*$H$2 -> 950 | I39: =$I$2*B39 -> 990 | J39: =$J$2*C39 -> 612 | K39: =-G39*3*0.5+0.5*G39 -> -310 | L39: =2*20 -> 40 | M39: =H39-SUM(I39:L39) -> -382
A40: =A38+2 -> 37 | B40: =B39 -> 330 | C40: =+C38+10 -> 180 | E40: High | F40: =IF((240+420)/2>($B40+$C40),($B40+$C40),(240+420)/2) -> 330 | G40: =C40+B40-F40 -> 180 | H40: =F40*$H$2 -> 1650 | I40: =$I$2*B40 -> 990 | J40: =$J$2*C40 -> 648 | K40: =-G40*3*0.5+0.5*G40 -> -180 | L40: =2*20 -> 40 | M40: =H40-SUM(I40:L40) -> 152 | N40: =M40*$N$2+M41*(1-$N$2) -> 40 | O40: =B40&"+"&C40 -> 330+180
...

Sheet iterations 8 (SL)
M1: Assumption
H2: 5 | I2: 3 | J2: 3.6 | M2: P(D=H⏐S=L) | N2: 0.4 | S2: P(S=H) | T2: 0.45
B3: Q0 | C3: Q1 | E3: Exp sales | G3: Exp left over | H3: Revenue | I3: Var cost | J3: Var cost | K3: refund cost | L3: ord cost | M3: Profit | N3: exp profit | O3: Q0+Q1 | P3: =N2*N4+'iterations 8 (SH)'!P4 -> 542.4 | S3: P(S=L) | T3: =1-T2 -> 0.55
A4: 1 | B4: 190 | C4: 0 | E4: High | F4: =IF((240+420)/2>($B4+$C4),($B4+$C4),(240+420)/2) -> 190 | G4: =C4+B4-F4 -> 0 | H4: =F4*$H$2 -> 950 | I4: =$I$2*B4 -> 570 | J4: =$J$2*C4 -> 0 | K4: =-G4*3*0.5+0.5*G4 -> 0 | L4: =2*20 -> 40 | M4: =H4-SUM(I4:L4) -> 340 | N4: =M4*$N$2+M5*(1-$N$2) -> 340 | O4: =B4&"+"&C4 -> 190+0 | S4: P(D=H⏐S=L) | T4: 0.4
B5: =B4 -> 190 | C5: =C4 -> 0 | E5: Low | F5: =IF((120+260)/2>($B5+$C5),($B5+$C5),(120+260)/2) -> 190 | G5: =C5+B5-F5 -> 0 | H5: =F5*$H$2 -> 950 | I5: =$I$2*B5 -> 570 | J5: =$J$2*C5 -> 0 | K5: =-G5*3*0.5+0.5*G5 -> 0 | L5: =2*20 -> 40 | M5: =H5-SUM(I5:L5) -> 340 | Q5: 170 | S5: P(D=L⏐S=L) | T5: =1-T4 -> 0.6
A6: =A4+2 -> 3 | B6: =B5 -> 190 | C6: =+C4+10 -> 10 | E6: High | F6: =IF((240+420)/2>($B6+$C6),($B6+$C6),(240+420)/2) -> 200 | G6: =C6+B6-F6 -> 0 | H6: =F6*$H$2 -> 1000 | I6: =$I$2*B6 -> 570 | J6: =$J$2*C6 -> 36 | K6: =-G6*3*0.5+0.5*G6 -> 0 | L6: =2*20 -> 40 | M6: =H6-SUM(I6:L6) -> 354 | N6: =M6*$N$2+M7*(1-$N$2) -> 330 | O6: =B6&"+"&C6 -> 190+10 | Q6: =Q5+10 -> 180 | S6: P(D=H⏐S=H) | T6: 0.8
B7: =B6 -> 190 | C7: =C6 -> 10 | E7: Low | F7: =IF((120+260)/2>($B7+$C7),($B7+$C7),(120+260)/2) -> 190 | G7: =C7+B7-F7 -> 10 | H7: =F7*$H$2 -> 950 | I7: =$I$2*B7 -> 570 | J7: =$J$2*C7 -> 36 | K7: =-G7*3*0.5+0.5*G7 -> -10 | L7: =2*20 -> 40 | M7: =H7-SUM(I7:L7) -> 314 | Q7: =Q6+10 -> 190 | S7: P(D=L⏐S=H) | T7: =1-T6 -> 0.2
A8: =A6+2 -> 5 | B8: =B7 -> 190 | C8: =+C6+10 -> 20 | E8: High | F8: =IF((240+420)/2>($B8+$C8),($B8+$C8),(240+420)/2) -> 210 | G8: =C8+B8-F8 -> 0 | H8: =F8*$H$2 -> 1050 | I8: =$I$2*B8 -> 570 | J8: =$J$2*C8 -> 72 | K8: =-G8*3*0.5+0.5*G8 -> 0 | L8: =2*20 -> 40 | M8: =H8-SUM(I8:L8) -> 368 | N8: =M8*$N$2+M9*(1-$N$2) -> 320 | O8: =B8&"+"&C8 -> 190+20 | Q8: =Q7+10 -> 200
B9: =B8 -> 190 | C9: =C8 -> 20 | E9: Low | F9: =IF((120+260)/2>($B9+$C9),($B9+$C9),(120+260)/2) -> 190 | G9: =C9+B9-F9 -> 20 | H9: =F9*$H$2 -> 950 | I9: =$I$2*B9 -> 570 | J9: =$J$2*C9 -> 72 | K9: =-G9*3*0.5+0.5*G9 -> -20 | L9: =2*20 -> 40 | M9: =H9-SUM(I9:L9) -> 288 | Q9: =Q8+10 -> 210
A10: =A8+2 -> 7 | B10: =B9 -> 190 | C10: =+C8+10 -> 30 | E10: High | F10: =IF((240+420)/2>($B10+$C10),($B10+$C10),(240+420)/2) -> 220 | G10: =C10+B10-F10 -> 0 | H10: =F10*$H$2 -> 1100 | I10: =$I$2*B10 -> 570 | J10: =$J$2*C10 -> 108 | K10: =-G10*3*0.5+0.5*G10 -> 0 | L10: =2*20 -> 40 | M10: =H10-SUM(I10:L10) -> 382 | N10: =M10*$N$2+M11*(1-$N$2) -> 310 | O10: =B10&"+"&C10 -> 190+30 | Q10: =Q9+10 -> 220
B11: =B10 -> 190 | C11: =C10 -> 30 | E11: Low | F11: =IF((120+260)/2>($B11+$C11),($B11+$C11),(120+260)/2) -> 190 | G11: =C11+B11-F11 -> 30 | H11: =F11*$H$2 -> 950 | I11: =$I$2*B11 -> 570 | J11: =$J$2*C11 -> 108 | K11: =-G11*3*0.5+0.5*G11 -> -30 | L11: =2*20 -> 40 | M11: =H11-SUM(I11:L11) -> 262 | Q11: =Q10+10 -> 230
A12: =A10+2 -> 9 | B12: =B11 -> 190 | C12: =+C10+10 -> 40 | E12: High | F12: =IF((240+420)/2>($B12+$C12),($B12+$C12),(240+420)/2) -> 230 | G12: =C12+B12-F12 -> 0 | H12: =F12*$H$2 -> 1150 | I12: =$I$2*B12 -> 570 | J12: =$J$2*C12 -> 144 | K12: =-G12*3*0.5+0.5*G12 -> 0 | L12: =2*20 -> 40 | M12: =H12-SUM(I12:L12) -> 396 | N12: =M12*$N$2+M13*(1-$N$2) -> 300 | O12: =B12&"+"&C12 -> 190+40 | Q12: =Q11+10 -> 240
B13: =B12 -> 190 | C13: =C12 -> 40 | E13: Low | F13: =IF((120+260)/2>($B13+$C13),($B13+$C13),(120+260)/2) -> 190 | G13: =C13+B13-F13 -> 40 | H13: =F13*$H$2 -> 950 | I13: =$I$2*B13 -> 570 | J13: =$J$2*C13 -> 144 | K13: =-G13*3*0.5+0.5*G13 -> -40 | L13: =2*20 -> 40 | M13: =H13-SUM(I13:L13) -> 236 | Q13: =Q12+10 -> 250 | S13: P(S=L⏐D=H)= | T13: P(D=H⏐S=L)P(S=L) | W13: =T4*T3/(T4*T3+T6*T2) -> 0.37931034
A14: =A12+2 -> 11 | B14: =B13 -> 190 | C14: =+C12+10 -> 50 | E14: High | F14: =IF((240+420)/2>($B14+$C14),($B14+$C14),(240+420)/2) -> 240 | G14: =C14+B14-F14 -> 0 | H14: =F14*$H$2 -> 1200 | I14: =$I$2*B14 -> 570 | J14: =$J$2*C14 -> 180 | K14: =-G14*3*0.5+0.5*G14 -> 0 | L14: =2*20 -> 40 | M14: =H14-SUM(I14:L14) -> 410 | N14: =M14*$N$2+M15*(1-$N$2) -> 290 | O14: =B14&"+"&C14 -> 190+50 | Q14: =Q13+10 -> 260 | T14: [P(D=H⏐S=L)P(S=L)+P(D=H⏐S=H)P(S=H)]
B15: =B14 -> 190 | C15: =C14 -> 50 | E15: Low | F15: =IF((120+260)/2>($B15+$C15),($B15+$C15),(120+260)/2) -> 190 | G15: =C15+B15-F15 -> 50 | H15: =F15*$H$2 -> 950 | I15: =$I$2*B15 -> 570 | J15: =$J$2*C15 -> 180 | K15: =-G15*3*0.5+0.5*G15 -> -50 | L15: =2*20 -> 40 | M15: =H15-SUM(I15:L15) -> 210 | Q15: =Q14+10 -> 270
A16: =A14+2 -> 13 | B16: =B15 -> 190 | C16: =+C14+10 -> 60 | E16: High | F16: =IF((240+420)/2>($B16+$C16),($B16+$C16),(240+420)/2) -> 250 | G16: =C16+B16-F16 -> 0 | H16: =F16*$H$2 -> 1250 | I16: =$I$2*B16 -> 570 | J16: =$J$2*C16 -> 216 | K16: =-G16*3*0.5+0.5*G16 -> 0 | L16: =2*20 -> 40 | M16: =H16-SUM(I16:L16) -> 424 | N16: =M16*$N$2+M17*(1-$N$2) -> 280 | O16: =B16&"+"&C16 -> 190+60 | Q16: =Q15+10 -> 280 | S16: P(S=H⏐D=H)= | W16: =1-W13 -> 0.62068966
B17: =B16 -> 190 | C17: =C16 -> 60 | E17: Low | F17: =IF((120+260)/2>($B17+$C17),($B17+$C17),(120+260)/2) -> 190 | G17: =C17+B17-F17 -> 60 | H17: =F17*$H$2 -> 950 | I17: =$I$2*B17 -> 570 | J17: =$J$2*C17 -> 216 | K17: =-G17*3*0.5+0.5*G17 -> -60 | L17: =2*20 -> 40 | M17: =H17-SUM(I17:L17) -> 184 | Q17: =Q16+10 -> 290
A18: =A16+2 -> 15 | B18: =B17 -> 190 | C18: =+C16+10 -> 70 | E18: High | F18: =IF((240+420)/2>($B18+$C18),($B18+$C18),(240+420)/2) -> 260 | G18: =C18+B18-F18 -> 0 | H18: =F18*$H$2 -> 1300 | I18: =$I$2*B18 -> 570 | J18: =$J$2*C18 -> 252 | K18: =-G18*3*0.5+0.5*G18 -> 0 | L18: =2*20 -> 40 | M18: =H18-SUM(I18:L18) -> 438 | N18: =M18*$N$2+M19*(1-$N$2) -> 270 | O18: =B18&"+"&C18 -> 190+70 | Q18: =Q17+10 -> 300 | S18: P(S=L⏐D=L)= | T18: P(D=L⏐S=L)P(S=L) | W18: =(T5*T3)/(T5*T3+T7*T2) -> 0.78571429
B19: =B18 -> 190 | C19: =C18 -> 70 | E19: Low | F19: =IF((120+260)/2>($B19+$C19),($B19+$C19),(120+260)/2) -> 190 | G19: =C19+B19-F19 -> 70 | H19: =F19*$H$2 -> 950 | I19: =$I$2*B19 -> 570 | J19: =$J$2*C19 -> 252 | K19: =-G19*3*0.5+0.5*G19 -> -70 | L19: =2*20 -> 40 | M19: =H19-SUM(I19:L19) -> 158 | Q19: =Q18+10 -> 310 | T19: [P(D=L⏐S=L)P(S=L)+P(D=L⏐S=H)P(S=H)]
A20: =A18+2 -> 17 | B20: =B19 -> 190 | C20: =+C18+10 -> 80 | E20: High | F20: =IF((240+420)/2>($B20+$C20),($B20+$C20),(240+420)/2) -> 270 | G20: =C20+B20-F20 -> 0 | H20: =F20*$H$2 -> 1350 | I20: =$I$2*B20 -> 570 | J20: =$J$2*C20 -> 288 | K20: =-G20*3*0.5+0.5*G20 -> 0 | L20: =2*20 -> 40 | M20: =H20-SUM(I20:L20) -> 452 | N20: =M20*$N$2+M21*(1-$N$2) -> 260 | O20: =B20&"+"&C20 -> 190+80 | Q20: =Q19+10 -> 320
